Workbook

Sheet Resumo
B1: PAINEL DE CUSTOS — GRUPO DTEL | E1: MES_BLOCO | F1: OFFSET
E2: ABRIL/2026 | F2: 2
B3: Selecione o mês: | C3: 46204 | E3: MAIO/2026 | F3: 61
E4: JUNHO/2026 | F4: 120
B5: Adm atendimento | E5: JULHO/2026 | F5: 179
B6: Comercial corporativo
B7: Compras
B8: Configuração
B9: Contabilidade
B10: Desenvolvimento
B11: DP
B12: Engenharia - Adm Engenharia
B13: Engenharia - Equipe de Josadark
B14: Engenharia - Equipe de Leonardo
B15: Estoque
B16: Financeiro
B17: Fique móvel
... B26: TOTAL SETORES
B28: COMERCIAL — POR EMPRESA | C28: TOTAL
B29: DTEL
B30: DX2
B31: VOICE NET
B32: SOARES E SILVA
B33: SOARES E LINS
B34: SOUZA E SILVA
B35: LITORAL NET
B36: TOTAL COMERCIAL
B38: REEMBOLSO GERAL
B40: TOTAL GERAL DO MÊS

Sheet Base Setores
A1: MÊS | B1: SETOR | C1: DESPESA | D1: QTD | E1: VALOR UN. | F1: VALOR TOTAL | G1: OBS | H1: Nº CLIENTES | I1: BASE DE CLIENTES | J1: CUSTO UNIT. / CLIENTE (R$) | L1: TOTAL (respeita o filtro):
A2: ABRIL/2026 | B2: Adm atendimento | C2: Folha trabalhista | D2: 10 | E2: 33427.48 | F2: =E2 -> 33427.48 | H2: 189453 | I2: Clientes, com H&A | J2: =IFERROR(SUMIFS($F$2:$F$1749,$A$2:$A$1749,A2,$B$2:$B$1749,B2)/H2,"") -> 0.1870984
A3: ABRIL/2026 | B3: Adm atendimento | C3: Seg. Trabalho | D3: 10 | E3: 45.310245 | F3: =D3*E3 -> 453.10245 | H3: 189453 | I3: Clientes, com H&A | J3: =IFERROR(SUMIFS($F$2:$F$1749,$A$2:$A$1749,A3,$B$2:$B$1749,B3)/H3,"") -> 0.1870984
A4: ABRIL/2026 | B4: Adm atendimento | C4: RH | D4: 10 | E4: 24.798868 | F4: =D4*E4 -> 247.98868 | H4: 189453 | I4: Clientes, com H&A | J4: =IFERROR(SUMIFS($F$2:$F$1749,$A$2:$A$1749,A4,$B$2:$B$1749,B4)/H4,"") -> 0.1870984
A5: ABRIL/2026 | B5: Adm atendimento | C5: DP | D5: 10 | E5: 40.668213 | F5: =D5*E5 -> 406.68213 | H5: 189453 | I5: Clientes, com H&A | J5: =IFERROR(SUMIFS($F$2:$F$1749,$A$2:$A$1749,A5,$B$2:$B$1749,B5)/H5,"") -> 0.1870984
A6: ABRIL/2026 | B6: Adm atendimento | C6: EMAIL | D6: 10 | E6: 50 | F6: =D6*E6 -> 500 | H6: 189453 | I6: Clientes, com H&A | J6: =IFERROR(SUMIFS($F$2:$F$1749,$A$2:$A$1749,A6,$B$2:$B$1749,B6)/H6,"") -> 0.1870984
A7: ABRIL/2026 | B7: Adm atendimento | C7: Linhas moveis fique movel | D7: 5 | E7: 30 | F7: =D7*E7 -> 150 | H7: 189453 | I7: Clientes, com H&A | J7: =IFERROR(SUMIFS($F$2:$F$1749,$A$2:$A$1749,A7,$B$2:$B$1749,B7)/H7,"") -> 0.1870984
A8: ABRIL/2026 | B8: Adm atendimento | C8: Gympass | D8: 10 | E8: 10.15 | F8: =D8*E8 -> 101.5 | H8: 189453 | I8: Clientes, com H&A | J8: =IFERROR(SUMIFS($F$2:$F$1749,$A$2:$A$1749,A8,$B$2:$B$1749,B8)/H8,"") -> 0.1870984
A9: ABRIL/2026 | B9: Adm atendimento | C9: Stargrid | D9: 10 | E9: 2.92 | F9: =D9*E9 -> 29.2 | H9: 189453 | I9: Clientes, com H&A | J9: =IFERROR(SUMIFS($F$2:$F$1749,$A$2:$A$1749,A9,$B$2:$B$1749,B9)/H9,"") -> 0.1870984
A10: ABRIL/2026 | B10: Adm atendimento | C10: Rescisões | D10: 0 | E10: 0 | F10: =D10*E10 -> 0 | H10: 189453 | I10: Clientes, com H&A | J10: =IFERROR(SUMIFS($F$2:$F$1749,$A$2:$A$1749,A10,$B$2:$B$1749,B10)/H10,"") -> 0.1870984
A11: ABRIL/2026 | B11: Adm atendimento | C11: Fardamento | D11: 0 | E11: 0 | F11: =D11*E11 -> 0 | H11: 189453 | I11: Clientes, com H&A | J11: =IFERROR(SUMIFS($F$2:$F$1749,$A$2:$A$1749,A11,$B$2:$B$1749,B11)/H11,"") -> 0.1870984
A12: ABRIL/2026 | B12: Adm atendimento | C12: Fardamento substituição | D12: 0 | E12: 0 | F12: =D12*E12 -> 0 | H12: 189453 | I12: Clientes, com H&A | J12: =IFERROR(SUMIFS($F$2:$F$1749,$A$2:$A$1749,A12,$B$2:$B$1749,B12)/H12,"") -> 0.1870984
A13: ABRIL/2026 | B13: Adm atendimento | C13: Exames médicos | D13: 0 | E13: 0 | F13: =D13*E13 -> 0 | H13: 189453 | I13: Clientes, com H&A | J13: =IFERROR(SUMIFS($F$2:$F$1749,$A$2:$A$1749,A13,$B$2:$B$1749,B13)/H13,"") -> 0.1870984
A14: ABRIL/2026 | B14: Adm atendimento | C14: Mat. uso coletivo | D14: 1 | E14: 130.4 | F14: =D14*E14 -> 130.4 | G14: Total dos itens (Materiais dos setores.xlsx) | H14: 189453 | I14: Clientes, com H&A | J14: =IFERROR(SUMIFS($F$2:$F$1749,$A$2:$A$1749,A14,$B$2:$B$1749,B14)/H14,"") -> 0.1870984
A15: ABRIL/2026 | B15: Adm atendimento | C15: Mat. Escritório | D15: 1 | E15: 0 | F15: =D15*E15 -> 0 | G15: Total dos itens (Materiais dos setores.xlsx) | H15: 189453 | I15: Clientes, com H&A | J15: =IFERROR(SUMIFS($F$2:$F$1749,$A$2:$A$1749,A15,$B$2:$B$1749,B15)/H15,"") -> 0.1870984
A16: ABRIL/2026 | B16: Adm atendimento | C16: Alimentação | D16: 0 | E16: 0 | F16: =D16*E16 -> 0 | H16: 189453 | I16: Clientes, com H&A | J16: =IFERROR(SUMIFS($F$2:$F$1749,$A$2:$A$1749,A16,$B$2:$B$1749,B16)/H16,"") -> 0.1870984
A17: ABRIL/2026 | B17: C.O.E | C17: Folha trabalhista | D17: 15 | E17: 73051.42 | F17: =E17 -> 73051.42 | H17: 165302 | I17: Clientes | J17: =IFERROR(SUMIFS($F$2:$F$1749,$A$2:$A$1749,A17,$B$2:$B$1749,B17)/H17,"") -> 0.45770245
A18: ABRIL/2026 | B18: C.O.E | C18: Seg. Trabalho | D18: 15 | E18: 45.310245 | F18: =D18*E18 -> 679.65367 | H18: 165302 | I18: Clientes | J18: =IFERROR(SUMIFS($F$2:$F$1749,$A$2:$A$1749,A18,$B$2:$B$1749,B18)/H18,"") -> 0.45770245
A19: ABRIL/2026 | B19: C.O.E | C19: RH | D19: 15 | E19: 24.798868 | F19: =D19*E19 -> 371.98302 | H19: 165302 | I19: Clientes | J19: =IFERROR(SUMIFS($F$2:$F$1749,$A$2:$A$1749,A19,$B$2:$B$1749,B19)/H19,"") -> 0.45770245
A20: ABRIL/2026 | B20: C.O.E | C20: DP | D20: 15 | E20: 40.668213 | F20: =D20*E20 -> 610.02319 | H20: 165302 | I20: Clientes | J20: =IFERROR(SUMIFS($F$2:$F$1749,$A$2:$A$1749,A20,$B$2:$B$1749,B20)/H20,"") -> 0.45770245
A21: ABRIL/2026 | B21: C.O.E | C21: EMAIL | D21: 6 | E21: 50 | F21: =D21*E21 -> 300 | H21: 165302 | I21: Clientes | J21: =IFERROR(SUMIFS($F$2:$F$1749,$A$2:$A$1749,A21,$B$2:$B$1749,B21)/H21,"") -> 0.45770245
A22: ABRIL/2026 | B22: C.O.E | C22: Exames medicos | D22: 0 | E22: 0 | F22: =D22*E22 -> 0 | H22: 165302 | I22: Clientes | J22: =IFERROR(SUMIFS($F$2:$F$1749,$A$2:$A$1749,A22,$B$2:$B$1749,B22)/H22,"") -> 0.45770245
A23: ABRIL/2026 | B23: C.O.E | C23: Linhas moveis vivo | D23: 0 | E23: 0 | F23: =D23*E23 -> 0 | H23: 165302 | I23: Clientes | J23: =IFERROR(SUMIFS($F$2:$F$1749,$A$2:$A$1749,A23,$B$2:$B$1749,B23)/H23,"") -> 0.45770245
A24: ABRIL/2026 | B24: C.O.E | C24: Linhas moveis fique movel | D24: 15 | E24: 30 | F24: =D24*E24 -> 450 | H24: 165302 | I24: Clientes | J24: =IFERROR(SUMIFS($F$2:$F$1749,$A$2:$A$1749,A24,$B$2:$B$1749,B24)/H24,"") -> 0.45770245
A25: ABRIL/2026 | B25: C.O.E | C25: Impressora | D25: 0 | E25: 0 | F25: =D25*E25 -> 0 | H25: 165302 | I25: Clientes | J25: =IFERROR(SUMIFS($F$2:$F$1749,$A$2:$A$1749,A25,$B$2:$B$1749,B25)/H25,"") -> 0.45770245
A26: ABRIL/2026 | B26: C.O.E | C26: Gympass | D26: 15 | E26: 10.15 | F26: =D26*E26 -> 152.25 | H26: 165302 | I26: Clientes | J26: =IFERROR(SUMIFS($F$2:$F$1749,$A$2:$A$1749,A26,$B$2:$B$1749,B26)/H26,"") -> 0.45770245
A27: ABRIL/2026 | B27: C.O.E | C27: Stargrid | D27: 15 | E27: 2.92 | F27: =D27*E27 -> 43.8 | H27: 165302 | I27: Clientes | J27: =IFERROR(SUMIFS($F$2:$F$1749,$A$2:$A$1749,A27,$B$2:$B$1749,B27)/H27,"") -> 0.45770245
A28: ABRIL/2026 | B28: C.O.E | C28: Rescisões Trabalhistas | D28: 0 | E28: 0 | F28: =D28*E28 -> 0 | H28: 165302 | I28: Clientes | J28: =IFERROR(SUMIFS($F$2:$F$1749,$A$2:$A$1749,A28,$B$2:$B$1749,B28)/H28,"") -> 0.45770245
A29: ABRIL/2026 | B29: C.O.E | C29: Fardamento novo | D29: 0 | E29: 0 | F29: =D29*E29 -> 0 | H29: 165302 | I29: Clientes | J29: =IFERROR(SUMIFS($F$2:$F$1749,$A$2:$A$1749,A29,$B$2:$B$1749,B29)/H29,"") -> 0.45770245
... A32: ABRIL/2026 | B32: C.O.E | C32: Mat. uso coletivo | D32: 0 | E32: 0 | F32: =D32*E32 -> 0 | H32: 165302 | I32: Clientes | J32: =IFERROR(SUMIFS($F$2:$F$1749,$A$2:$A$1749,A32,$B$2:$B$1749,B32)/H32,"") -> 0.45770245
A33: ABRIL/2026 | B33: Comercial corporativo | C33: Folha trabalhista | D33: 9 | E33: 88730.25 | F33: =E33 -> 88730.25 | H33: 189453 | I33: Clientes, com H&A | J33: =IFERROR(SUMIFS($F$2:$F$1749,$A$2:$A$1749,A33,$B$2:$B$1749,B33)/H33,"") -> 0.52393985
A34: ABRIL/2026 | B34: Comercial corporativo | C34: Seg. Trabalho | D34: 9 | E34: 45.310245 | F34: =D34*E34 -> 407.7922 | H34: 189453 | I34: Clientes, com H&A | J34: =IFERROR(SUMIFS($F$2:$F$1749,$A$2:$A$1749,A34,$B$2:$B$1749,B34)/H34,"") -> 0.52393985
A35: ABRIL/2026 | B35: Comercial corporativo | C35: RH | D35: 9 | E35: 24.798868 | F35: =D35*E35 -> 223.18981 | H35: 189453 | I35: Clientes, com H&A | J35: =IFERROR(SUMIFS($F$2:$F$1749,$A$2:$A$1749,A35,$B$2:$B$1749,B35)/H35,"") -> 0.52393985
A36: ABRIL/2026 | B36: Comercial corporativo | C36: DP | D36: 9 | E36: 40.668213 | F36: =D36*E36 -> 366.01391 | H36: 189453 | I36: Clientes, com H&A | J36: =IFERROR(SUMIFS($F$2:$F$1749,$A$2:$A$1749,A36,$B$2:$B$1749,B36)/H36,"") -> 0.52393985
A37: ABRIL/2026 | B37: Comercial corporativo | C37: EMAIL | D37: 9 | E37: 50 | F37: =D37*E37 -> 450 | H37: 189453 | I37: Clientes, com H&A | J37: =IFERROR(SUMIFS($F$2:$F$1749,$A$2:$A$1749,A37,$B$2:$B$1749,B37)/H37,"") -> 0.52393985
A38: ABRIL/2026 | B38: Comercial corporativo | C38: Linhas moveis claro | D38: 0 | E38: 0 | F38: =D38*E38 -> 0 | H38: 189453 | I38: Clientes, com H&A | J38: =IFERROR(SUMIFS($F$2:$F$1749,$A$2:$A$1749,A38,$B$2:$B$1749,B38)/H38,"") -> 0.52393985
A39: ABRIL/2026 | B39: Comercial corporativo | C39: Linhas moveis fique movel | D39: 7 | E39: 30 | F39: =D39*E39 -> 210 | H39: 189453 | I39: Clientes, com H&A | J39: =IFERROR(SUMIFS($F$2:$F$1749,$A$2:$A$1749,A39,$B$2:$B$1749,B39)/H39,"") -> 0.52393985
A40: ABRIL/2026 | B40: Comercial corporativo | C40: Gympass | D40: 9 | E40: 10.15 | F40: =D40*E40 -> 91.35 | H40: 189453 | I40: Clientes, com H&A | J40: =IFERROR(SUMIFS($F$2:$F$1749,$A$2:$A$1749,A40,$B$2:$B$1749,B40)/H40,"") -> 0.52393985
A41: ABRIL/2026 | B41: Comercial corporativo | C41: Stargrid | D41: 9 | E41: 2.92 | F41: =D41*E41 -> 26.28 | H41: 189453 | I41: Clientes, com H&A | J41: =IFERROR(SUMIFS($F$2:$F$1749,$A$2:$A$1749,A41,$B$2:$B$1749,B41)/H41,"") -> 0.52393985
A42: ABRIL/2026 | B42: Comercial corporativo | C42: Rescisões | D42: 0 | E42: 0 | F42: =D42*E42 -> 0 | H42: 189453 | I42: Clientes, com H&A | J42: =IFERROR(SUMIFS($F$2:$F$1749,$A$2:$A$1749,A42,$B$2:$B$1749,B42)/H42,"") -> 0.52393985
...

Sheet Comercial
A1: COMERCIAL — ABRIL 2026
A3: DTEL | D3: DX2 | G3: VOICE NET | J3: SOARES E SILVA | M3: Soares e lins | P3: Souza e Silva | S3: LITORAL NET
A4: Custos comerciais | B4: Valores | D4: Custos comerciais | E4: Valores | G4: Custos comerciais | H4: Valores | J4: Custos comerciais | K4: Valores | M4: Custos comerciais | N4: Valores | P4: Custos comerciais | Q4: Valores | S4: Custos comerciais | T4: Valores
A5: Valores de alimentação fora o mês | B5: 0 | D5: Valores de alimentação fora o mês | E5: 0 | G5: Valores de alimentação fora o mês | H5: 0 | J5: Valores de alimentação fora o mês | K5: 0 | M5: Valores de alimentação fora o mês | N5: 0 | P5: Valores de alimentação fora o mês | Q5: 0 | S5: Valores de alimentação fora o mês | T5: 0
A6: Despesas Trabalhistas extra folha | B6: 4905.36 | D6: Despesas Trabalhistas extra folha | E6: 0 | G6: Despesas Trabalhistas extra folha | H6: 11274.36 | J6: Despesas Trabalhistas extra folha | K6: 1785.97 | M6: Despesas Trabalhistas extra folha | N6: 0 | P6: Despesas Trabalhistas extra folha | Q6: 2365.44 | S6: Despesas Trabalhistas extra folha | T6: 3219.12
A7: Endomarketing | B7: 0 | D7: Marketing direto | E7: 0 | G7: Marketing direto | H7: 0 | J7: Endomarketing | K7: 0 | M7: Endomarketing | N7: 0 | P7: Endomarketing | Q7: 0 | S7: Endomarketing | T7: 0
A8: Marketing direto | B8: 0 | D8: E-mail do departamento (1 email) | E8: 50 | G8: E-mail do departamento (4 email) | H8: 120 | J8: E-mail do departamento (2 email) | K8: 50 | M8: Marketing direto | N8: 0 | P8: Marketing direto | Q8: 0 | S8: Marketing direto | T8: 0
A9: E-mail do departamento (11 emails) | B9: 350 | D9: Folha Trabalhista com impostos do mês | E9: 22072.83 | G9: Folha Trabalhista com impostos do mês | H9: 6378.71 | J9: Folha Trabalhista com impostos do mês | K9: 37856.07 | M9: E-mail do departamento | N9: 0 | P9: E-mail do departamento | Q9: 0 | S9: E-mail do departamento (1 email) | T9: 10
A10: Folha Trabalhista com impostos do mês | B10: 231241.42 | D10: Vexpenses | E10: 0 | G10: Vale Transporte | H10: 1026 | J10: Vale Transporte | K10: 2615 | M10: Folha Trabalhista com impostos do mês | N10: 3360.44 | P10: Folha Trabalhista com impostos do mês | Q10: 12661.55 | S10: Folha Trabalhista com impostos do mês | T10: 0
A11: Vale Transporte | B11: 3960 | D11: Linhas moveis (FIQUE MÓVEL) | E11: 300 | G11: Linhas moveis (FIQUE MÓVEL) | H11: 210 | J11: KM Rodado R$ Vexpenses | K11: 0 | M11: Vale Transporte | N11: 0 | P11: Vale Transporte | Q11: 0 | S11: Vale Transporte | T11: 216
A12: Linhas moveis (FIQUE MÓVEL) | B12: 2520 | D12: Despesas com RH | E12: =E36*B47 -> 224.32 | G12: Despesas com RH | H12: =H36*B47 -> 196.28 | J12: Linhas moveis (FIQUE MÓVEL) | K12: 360 | M12: Linhas moveis (FIQUE MÓVEL) | N12: 120 | P12: Linhas moveis (FIQUE MÓVEL) | Q12: 60 | S12: Linhas moveis (FIQUE MÓVEL) | T12: 90
A13: Despesas com RH | B13: =B36*B47 -> 1542.2 | D13: Despesas com DP | E13: =E36*B48 -> 292.56 | G13: Despesas com DP | H13: =H36*B48 -> 255.99 | J13: Despesas com RH | K13: =K36*B47 -> 392.56 | M13: Despesas com RH | N13: =N36*B47 -> 28.04 | P13: Despesas com RH | Q13: =Q36*B47 -> 140.2 | S13: Despesas com RH | T13: =T36*B47 -> 28.04
A14: Despesas com DP | B14: =B36*B48 -> 2011.35 | D14: Despesas com SST | E14: =E36*B49 -> 356 | G14: Despesas com SST | H14: =H36*B49 -> 311.5 | J14: Despesas com DP | K14: =K36*B48 -> 511.98 | M14: Despesas com DP | N14: =N36*B48 -> 36.57 | P14: Despesas com DP | Q14: =Q36*B48 -> 182.85 | S14: Despesas com DP | T14: =T36*B48 -> 36.57
A15: Despesas com SST | B15: =B36*B49 -> 2447.5 | D15: Despesas SST exames | E15: 180 | G15: Despesas SST exames | H15: 121 | J15: Despesas com SST | K15: =K36*B49 -> 623 | M15: Despesas com SST | N15: =N36*B49 -> 44.5 | P15: Despesas com SST | Q15: =Q36*B49 -> 222.5 | S15: Despesas com SST | T15: =T36*B49 -> 44.5
A16: Despesas SST exames | B16: 194.6 | D16: Novo Fardamento | E16: 0 | G16: Devolução fardamento | H16: -271.8 | J16: Despesas SST exames | K16: 770 | M16: Devolução de fardamento | N16: 0 | P16: Despesas SST exames | Q16: 360 | S16: Despesas SST exames | T16: 0
A17: Novo Fardamento | B17: 94.42 | D17: Devolução de fardamento | E17: 0 | G17: Novo Fardamento | H17: 0 | J17: Devolução fardamento | K17: -1076.34 | M17: Novo Fardamento | N17: 0 | P17: Novo Fardamento | Q17: 984.16 | S17: Novo Fardamento | T17: 0
A18: Devolução de fardamento | B18: -951.3 | D18: Substituição extra de Fardamento | E18: 0 | G18: Substituição extra de Fardamento | H18: 0 | J18: Novo Fardamento | K18: 1556.24 | M18: Substituição extra de Fardamento | N18: 0 | P18: Devolução de fardamento | Q18: -358.78 | S18: Substituição extra de Fardamento | T18: 0
A19: Substituição extra de Fardamento | B19: 130.14 | D19: Combustivel de TIAGO | E19: 821.42 | G19: Combustivel RENAN RAFAEL | H19: 315.97 | J19: Substituição extra de Fardamento | K19: 0 | M19: Gympass | N19: =N36*B50 -> 11.37 | P19: Substituição extra de Fardamento | Q19: 0 | S19: Devoulução de fardamento | T19: -358.78
A20: Consumo de combustivel 4 VANs | B20: 9096.55 | D20: Gympass | E20: =E36*B50 -> 90.96 | G20: Combustivel CARLOS ROBERTO | H20: 1639.8 | J20: Consumo de combustível jefferson | K20: 1346.19 | M20: Stargrid | N20: =N36*B51 -> 2.24 | P20: Gympass | Q20: =Q36*B50 -> 56.85 | S20: Combustivel Jose gabriel | T20: 223.46
A21: Combustível Alvaro (kombi) | B21: 1719.94 | D21: Stargrid | E21: =E36*B51 -> 17.92 | G21: Discador | H21: 447.13 | J21: Consumo de combustível Camila Cordeiro | K21: 37.08 | M21: Total | P21: Stargrid | Q21: =Q36*B51 -> 11.2 | S21: Gympass | T21: =T36*B50 -> 11.37
A22: Combustivel Tarcizio | B22: 1124.73 | D22: Total | G22: Gympass | H22: =H36*B50 -> 79.59 | J22: Consumo de combustível KATHERINE | K22: 724.64 | P22: Total | S22: Stargrid | T22: =T36*B51 -> 2.24
A23: Combustivel de Nedson(executivo) | B23: 782.36 | G23: Stargrid | H23: =H36*B51 -> 15.68 | J23: Gympass | K23: =K36*B50 -> 159.18 | S23: Total
A24: Combustivel jean pereira(executivo) | B24: 139.54 | G24: Total | J24: Stargrid | K24: =K36*B51 -> 31.36
A25: Combustivel Elthon | B25: 988.16 | J25: Combustivel Manoel lopes(executivo) | K25: 782.2
A26: Combustivel rayanne meneses(executivo) | B26: 156.23 | J26: Total
A27: Combustivel myllena kelly (executiva) | B27: 1014.69
A28: Combustivel Denise kelline | B28: 1068.57
A29: Combustivel joyce rayanna | B29: 350
A30: Combustivel Djalma (executivo) | B30: 330.41
A31: Gympass | B31: =B36*B50 -> 625.35
A32: Stargrid | B32: =B36*B51 -> 123.2
A33: Total
A36: Nº Colaboradores | B36: 55 | D36: Nº Colaboradores | E36: 8 | G36: Nº Colaboradores | H36: 7 | J36: Nº Colaboradores | K36: 14 | M36: Nº Colaboradores | N36: 1 | P36: Nº Colaboradores | Q36: 5 | S36: Nº Colaboradores | T36: 1
A37: Qtd. analise | B37: 0 | D37: Qtd. analise | E37: 0 | G37: Qtd. analise | H37: 0 | J37: Qtd. analise | K37: 0 | M37: Qtd. analise | N37: 0 | P37: Qtd. analise | Q37: 0 | S37: Qtd. analise | T37: 0
A38: Vendas instaladas | B38: 1781 | D38: Vendas instaladas | E38: 136 | G38: Vendas instaladas | H38: 63 | J38: Vendas instaladas | K38: 149 | M38: Vendas instaladas | N38: 34 | P38: Vendas instaladas | Q38: 21 | S38: Vendas instaladas | T38: 9
A39: Upgrade | B39: 16 | D39: Upgrade | E39: 3 | G39: Upgrade | H39: 1 | J39: Upgrade | K39: 0 | M39: Upgrade | N39: 1 | P39: Upgrade | Q39: 1 | S39: Upgrade | T39: 0
A41: Receita vendas instaladas | B41: 147589.25 | D41: Receita vendas instaladas | E41: 10986.18 | G41: Receita vendas instaladas | H41: 5519.56 | J41: Receita vendas instaladas | K41: 14226.45 | M41: Receita vendas instaladas | N41: 3391.87 | P41: Receita vendas instaladas | Q41: 1453.39 | S41: Receita vendas instaladas | T41: 719.1
A42: Receita upgrade | B42: 375.32 | D42: Receita upgrade | E42: 24.98 | G42: Receita upgrade | H42: 4.99 | J42: Receita upgrade | K42: 0 | M42: Receita upgrade | N42: 39.99 | P42: Receita upgrade | Q42: 15 | S42: Receita upgrade | T42: 0
A43: Soma de Receita
A45: Valor da venda despesas/qtd instalada | D45: Valor da venda despesas/qtd instalada | G45: Valor da venda despesas/qtd instalada | J45: Valor da venda despesas/qtd instalada | M45: Valor da venda despesas/qtd instalada | P45: Valor da venda despesas/qtd instalada | S45: Valor da venda despesas/qtd instalada
...

Sheet Reembolso Geral
A1: MÊS | B1: Descrição | C1: Setor/ Departamento | D1: Competência | E1: Empresa | F1: QTD referência | G1: Valor uni. | H1: Valor total | I1: FORMA DE CÁLCULO
A2: ABRIL/2026 | B2: Despesa do consultor PEDRO GREGO | C2: Comercial | D2: 46113 | E2: DX2 | F2: 3 | G2: 300.37 | H2: =IF(OR(F2="",G2=""),"",F2*G2) -> 901.11 | I2: despesa trabalhista e combustível do consultor dividido pelo total de vendas (cliente 12195,12634,12408)
A3: ABRIL/2026 | B3: Transporte de produtos | C3: Frota | D3: 46113 | E3: DX2 | F3: 0 | G3: 0 | H3: =IF(OR(F3="",G3=""),"",F3*G3) -> 0 | I3: transportes entre CD01 e empresas no rateio da rota
A4: ABRIL/2026 | B4: Adm atendimento presencial | C4: Adm Atendimento | D4: 46113 | E4: H&A | F4: 13402 | G4: 0.1870984 | H4: =IF(OR(F4="",G4=""),"",F4*G4) -> 2507.4928 | I4: Cálculo por número de clientes ativos
A5: ABRIL/2026 | B5: E-mail Dtel | C5: TIC | D5: 46113 | E5: H&A | F5: 2 | G5: 50 | H5: =IF(OR(F5="",G5=""),"",F5*G5) -> 100 | I5: Utilização de email corporativo
A6: ABRIL/2026 | B6: Vendas da equipe voicenet P/ SOARES E LINS | C6: Comercial | D6: 46113 | E6: Soares & Lins | F6: 0 | G6: 0 | H6: =IF(OR(F6="",G6=""),"",F6*G6) -> 0 | I6: Vendas instaladas
A7: ABRIL/2026 | B7: KM rodado para serviços técnicos da S&L para DTEL | C7: Instalação | D7: 46113 | E7: Soares & Lins | F7: 0 | G7: 0 | H7: =IF(OR(F7="",G7=""),"",F7*G7) -> 0 | I7: Deslocamento de equipes
A8: ABRIL/2026 | B8: Conselho Regional De Enfermagem De Alagoas | C8: Licitação | D8: 46113 | E8: Soares e Silva | F8: -1 | G8: 238.88 | H8: =IF(OR(F8="",G8=""),"",F8*G8) -> -238.88 | I8: mensalidade recebida pela H&A (parcela abril)
A9: ABRIL/2026 | B9: Fardamentos | C9: RH | D9: 46113 | E9: Souza & Silva | F9: 0 | G9: 0 | H9: =IF(OR(F9="",G9=""),"",F9*G9) -> 0 | I9: Solicitações de fardamentos administrativos
A10: ABRIL/2026 | B10: Despesa do consultor PAULO MELO | C10: Comercial | D10: 46113 | E10: Voicenet | F10: 2 | G10: 338.53 | H10: =IF(OR(F10="",G10=""),"",F10*G10) -> 677.06 | I10: despesa trabalhista e combustivel do consultor dividido pelo total de vendas(cliente 15826, 15746)
A11: ABRIL/2026 | B11: Vendas do site Mundiale | C11: Marketing | D11: 46113 | E11: Dtel Telecom | F11: 1 | G11: 404.4 | H11: =IF(OR(F11="",G11=""),"",F11*G11) -> 404.4 | I11: Vendas instaladas do impulsionamento site mundiale (VENDAS MUNDIALE - MAIO 2026.xlsx)
A12: ABRIL/2026 | B12: Vendas da equipe Dtel porta a porta | C12: Comercial | D12: 46114 | E12: DX2 | F12: 0 | G12: 0 | H12: =IF(OR(F12="",G12=""),"",F12*G12) -> 0 | I12: Vendas instaladas
A13: ABRIL/2026 | B13: Abastecimento | C13: Frota | D13: 46114 | E13: DX2 | F13: 0 | G13: 0 | H13: =IF(OR(F13="",G13=""),"",F13*G13) -> 0 | I13: Abastecimento da van da dx2 com cartao Dtel
... A35: ABRIL/2026 | B35: E-mail Dtel | C35: TIC | D35: 46116 | E35: Soares e Silva | F35: 5 | G35: 50 | H35: =IF(OR(F35="",G35=""),"",F35*G35) -> 250 | I35: Utilização de email corporativo
A36: ABRIL/2026 | B36: Vendas da equipe Dtel porta a porta | C36: Comercial | D36: 46116 | E36: Voicenet | F36: 4 | H36: =IF(OR(F36="",G36=""),"",F36*G36) | I36: Vendas instaladas
A37: ABRIL/2026 | B37: Conselho regional de farmacia dos estado de pernambuco | C37: Licitação | D37: 46116 | E37: Voicenet | F37: -1 | G37: 510 | H37: =IF(OR(F37="",G37=""),"",F37*G37) -> -510 | I37: mensalidade recebida pela H&A (parcela abril)
A38: ABRIL/2026 | B38: Vendas da equipe H&A porta a porta P/ DX2 | C38: Comercial | D38: 46117 | E38: DX2 | F38: 0 | G38: 0 | H38: =IF(OR(F38="",G38=""),"",F38*G38) -> 0 | I38: Vendas instaladas
A39: ABRIL/2026 | B39: Manutenção predial | C39: Manutenção | D39: 46117 | E39: DX2 | F39: 1 | G39: 7780.43 | H39: =IF(OR(F39="",G39=""),"",F39*G39) -> 7780.43 | I39: Serviços executados para verificação de tacaimbó, e manut. de alarme e sensor loja pesqueira, despesa com comb. e colab.
A40: ABRIL/2026 | B40: Equipamentos de Segurança | C40: SST | D40: 46117 | E40: DX2 | F40: 1 | G40: 13006.38 | H40: =IF(OR(F40="",G40=""),"",F40*G40) -> 13006.38 | I40: EPI, EPC, Fardamento
A41: ABRIL/2026 | B41: Rastreamento veicular | C41: Frota | D41: 46117 | E41: Soares & Lins | F41: 3 | G41: 20 | H41: =IF(OR(F41="",G41=""),"",F41*G41) -> 60 | I41: rastreamento dos veículos
A42: ABRIL/2026 | B42: Serviços técnicos da S&L para DTEL | C42: Instalação | D42: 46117 | E42: Soares & Lins | F42: -1 | G42: 4279.74 | H42: =IF(OR(F42="",G42=""),"",F42*G42) -> -4279.74 | I42: Serviços da equipe técnica
A43: ABRIL/2026 | B43: Reembolso por receita recebida | C43: Administrativo | D43: 46117 | E43: Soares e Silva | F43: 1 | G43: 36742.58 | H43: =IF(OR(F43="",G43=""),"",F43*G43) -> 36742.58 | I43: Taxa de administração de 6% e 1% de utilização da marca
A44: ABRIL/2026 | B44: Despesa do consultor PAULO MELO | C44: Comercial | D44: 46117 | E44: Soares e Silva | F44: 4 | G44: 338.53 | H44: =IF(OR(F44="",G44=""),"",F44*G44) -> 1354.12 | I44: despesa trabalhista e combustÍvel dividida pela quantidade de vendas(cliente 12023,11614)
A45: ABRIL/2026 | B45: E-mail Dtel | C45: TIC | D45: 46117 | E45: Solon araújo | F45: 2 | G45: 50 | H45: =IF(OR(F45="",G45=""),"",F45*G45) -> 100 | I45: Utilização de email corporativo
A46: ABRIL/2026 | B46: Vendas da equipe H&A p/ voice | C46: Comercial | D46: 46117 | E46: Voicenet | F46: 0 | G46: 0 | H46: =IF(OR(F46="",G46=""),"",F46*G46) -> 0 | I46: Vendas instaladas
A47: ABRIL/2026 | B47: Vendas da equipe VOICENET porta a porta P/ DX2 | C47: Comercial | D47: 46118 | E47: DX2 | F47: 0 | G47: 0 | H47: =IF(OR(F47="",G47=""),"",F47*G47) -> 0 | I47: Vendas instaladas
A48: ABRIL/2026 | B48: Manutenção predial | C48: Manutenção | D48: 46118 | E48: H&A | F48: 1 | G48: 2777.71 | H48: =IF(OR(F48="",G48=""),"",F48*G48) -> 2777.71 | I48: Despesa com combust. e colaborador para manutenção de ar condicionado do estoque
... A61: ABRIL/2026 | B61: Reembolso por receita recebida | C61: Administrativo | D61: 46119 | E61: Souza & Silva | F61: 1 | G61: 24090.35 | H61: =IF(OR(F61="",G61=""),"",F61*G61) -> 24090.35 | I61: Taxa de administração de 6% e 1% de utilização da marca
A62: ABRIL/2026 | B62: Vendas da equipe Voicenet para Dtel | C62: Comercial | D62: 46119 | E62: Voicenet | F62: -15 | H62: =IF(OR(F62="",G62=""),"",F62*G62) | I62: Vendas instaladas
A63: ABRIL/2026 | B63: E-mail Dtel | C63: TIC | D63: 46119 | E63: Voicenet | F63: 1 | G63: 90 | H63: =IF(OR(F63="",G63=""),"",F63*G63) -> 90 | I63: Utilização de email corporativo
A64: ABRIL/2026 | B64: Despesa do coordenador TIAGO, pela gestão da equipe | C64: Comercial | D64: 46120 | E64: DX2 | F64: -1 | G64: 812.42 | H64: =IF(OR(F64="",G64=""),"",F64*G64) -> -812.42 | I64: crédito por despesa com combustível e utilização de veÍculo dx2
A65: ABRIL/2026 | B65: Serviços de configuração e suporte ao Técnico | C65: Configuração | D65: 46120 | E65: DX2 | F65: 6280 | G65: 0.17862455 | H65: =IF(OR(F65="",G65=""),"",F65*G65) -> 1121.7621 | I65: Cálculo por número de clientes ativos
A66: ABRIL/2026 | B66: Saude e segurança no trabalho | C66: SST | D66: 46120 | E66: H&A | F66: 0 | G66: 0 | H66: =IF(OR(F66="",G66=""),"",F66*G66) -> 0 | I66: Rateio do departamento (despesa por colaborador, mês de jan fev e março)
A67: ABRIL/2026 | B67: Despesa do coordenador TIAGO, pela gestão da equipe | C67: Comercial | D67: 46120 | E67: Soares e Silva | F67: 149 | G67: 20.06 | H67: =IF(OR(F67="",G67=""),"",F67*G67) -> 2988.94 | I67: despesa trabalhista e pela quantidade de vendas
A68: ABRIL/2026 | B68: Abastecimento | C68: Frota | D68: 46120 | E68: Soares e silva | F68: 0 | G68: 0 | H68: =IF(OR(F68="",G68=""),"",F68*G68) -> 0 | I68: Abastecimento de 2 veiculos
A69: ABRIL/2026 | B69: Serviços técnicos da Dx2 p/ soares e silva | C69: Instalação | D69: 46120 | E69: Soares e Silva | F69: 0 | G69: 0 | H69: =IF(OR(F69="",G69=""),"",F69*G69) -> 0 | I69: Serviços das equipes técnicas
A70: ABRIL/2026 | B70: Manutenção predial | C70: Manutenção | D70: 46120 | E70: Soares e Silva | F70: 1 | G70: 4438.18 | H70: =IF(OR(F70="",G70=""),"",F70*G70) -> 4438.18 | I70: Serviços executados, despesa com combustÍvel e colaborador para reforma pop b, e passagem de tubulação de condensadora
A71: ABRIL/2026 | B71: Reembolso por receita recebida | C71: Administrativo | D71: 46120 | E71: Voicenet | F71: 1 | G71: 29402.21 | H71: =IF(OR(F71="",G71=""),"",F71*G71) -> 29402.21 | I71: Taxa de administração de 6% e 1% de utilização da marca
A72: ABRIL/2026 | B72: E-mail Dtel | C72: TIC | D72: 46120 | E72: Voicenet | F72: 2 | G72: 10 | H72: =IF(OR(F72="",G72=""),"",F72*G72) -> 20 | I72: Utilização de email corporativo
A73: ABRIL/2026 | B73: Material de escritório | C73: Atendimento | D73: 46121 | E73: DX2 | F73: 0 | G73: 0 | H73: =IF(OR(F73="",G73=""),"",F73*G73) -> 0 | I73: Capa de carnê
...

Sheet Parâmetros
A1: INFORMAÇÕES ADICIONAIS POR SETOR (clientes, custo por cliente/funcionário, observações — nada foi descartado)
A3: Adm atendimento
A4: [A17] Total
A5: [D17] fórmula original: =SUBTOTAL(109,D2:D16)
A6: [C18] Total clientes grupo dtel, com h&a
A7: [D18] 189453
A8: [D19] 0.19
A10: C.O.E
A11: [A18] Total
A12: [C18] fórmula original: =SUBTOTAL(109,C2:C17)
A13: [D18] fórmula original: =SUBTOTAL(109,D2:D17)
A14: [A19] nº de clientes menos h&a e dx2, e souza e silva pois estão fazendo a distribuição dos serviços
... A247: [B26] fórmula original: =Tabela56457[[#Totals],[Total]]/D25
