Workbook

Sheet PARÂMETROS
A1: PARÂMETROS DE RATEIO — EMPRESAS PARCEIRAS/LICENCIADAS
A3: Mês de referência:
A5: Preencha o Nº de Clientes atendidos e o Nº de Funcionários da Dtel alocados a cada empresa. Estes números definem o % de rateio de cada setor (conforme critério definido na aba SETORES). O % Royalty é opcional — deixe 0% enquanto o rateio for só a custo (ver nota jurídico-fiscal abaixo).
A7: Empresa | B7: Nº de Clientes Atendidos | C7: Nº de Funcionários Dtel Alocados | D7: % de Clientes | E7: % de Funcionários | F7: % Royalty | G7: Mês
A8: Empresa Licenciada DX2 | B8: 6445 | C8: 34 | D8: =IFERROR(B8/SUMIFS($B$8:$B$907,$G$8:$G$907,G8),0) -> 0.033077914 | E8: =IFERROR(C8/SUMIFS($C$8:$C$907,$G$8:$G$907,G8),0) -> 0.032411821 | F8: 0 | G8: Junho/2026
A9: Empresa Licenciada H&A | B9: 13418 | C9: 32 | D9: =IFERROR(B9/SUMIFS($B$8:$B$907,$G$8:$G$907,G9),0) -> 0.068865702 | E9: =IFERROR(C9/SUMIFS($C$8:$C$907,$G$8:$G$907,G9),0) -> 0.030505243 | F9: 0 | G9: Junho/2026
A10: Empresa Licenciada SOLON ARAUJO | B10: 14441 | C10: 42 | D10: =IFERROR(B10/SUMIFS($B$8:$B$907,$G$8:$G$907,G10),0) -> 0.074116083 | E10: =IFERROR(C10/SUMIFS($C$8:$C$907,$G$8:$G$907,G10),0) -> 0.040038132 | F10: 0 | G10: Junho/2026
A11: Empresa Licenciada SOARES E LINS | B11: 3704 | C11: 11 | D11: =IFERROR(B11/SUMIFS($B$8:$B$907,$G$8:$G$907,G11),0) -> 0.019010177 | E11: =IFERROR(C11/SUMIFS($C$8:$C$907,$G$8:$G$907,G11),0) -> 0.010486177 | F11: 0 | G11: Junho/2026
A12: Empresa Licenciada SOARES E SILVA | B12: 6434 | C12: 42 | D12: =IFERROR(B12/SUMIFS($B$8:$B$907,$G$8:$G$907,G12),0) -> 0.033021458 | E12: =IFERROR(C12/SUMIFS($C$8:$C$907,$G$8:$G$907,G12),0) -> 0.040038132 | F12: 0 | G12: Junho/2026
A13: Empresa Licenciada SOUZA E SILVA | B13: 4749 | C13: 18 | D13: =IFERROR(B13/SUMIFS($B$8:$B$907,$G$8:$G$907,G13),0) -> 0.02437347 | E13: =IFERROR(C13/SUMIFS($C$8:$C$907,$G$8:$G$907,G13),0) -> 0.017159199 | F13: 0 | G13: Junho/2026
A14: Empresa Licenciada VOICENET | B14: 4795 | C14: 17 | D14: =IFERROR(B14/SUMIFS($B$8:$B$907,$G$8:$G$907,G14),0) -> 0.024609557 | E14: =IFERROR(C14/SUMIFS($C$8:$C$907,$G$8:$G$907,G14),0) -> 0.01620591 | F14: 0 | G14: Junho/2026
A15: DTEL (uso próprio) | B15: 140857 | C15: 853 | D15: =IFERROR(B15/SUMIFS($B$8:$B$907,$G$8:$G$907,G15),0) -> 0.72292564 | E15: =IFERROR(C15/SUMIFS($C$8:$C$907,$G$8:$G$907,G15),0) -> 0.81315539 | F15: 0 | G15: Junho/2026
A16: TOTAL | B16: =SUM(B8:B15) -> 194843 | C16: =SUM(C8:C15) -> 1049
A17: Empresa Licenciada DX2 | B17: 6280 | C17: 35 | D17: =IFERROR(B17/SUMIFS($B$8:$B$907,$G$8:$G$907,G17),0) -> 0.032823386 | E17: =IFERROR(C17/SUMIFS($C$8:$C$907,$G$8:$G$907,G17),0) -> 0.033238367 | F17: 0 | G17: Maio/2026
A18: Empresa Licenciada H&A | B18: 13402 | C18: 35 | D18: =IFERROR(B18/SUMIFS($B$8:$B$907,$G$8:$G$907,G18),0) -> 0.070047615 | E18: =IFERROR(C18/SUMIFS($C$8:$C$907,$G$8:$G$907,G18),0) -> 0.033238367 | F18: 0 | G18: Maio/2026
A19: Empresa Licenciada SOLON ARAUJO | B19: 14331 | C19: 42 | D19: =IFERROR(B19/SUMIFS($B$8:$B$907,$G$8:$G$907,G19),0) -> 0.074903176 | E19: =IFERROR(C19/SUMIFS($C$8:$C$907,$G$8:$G$907,G19),0) -> 0.03988604 | F19: 0 | G19: Maio/2026
A20: Empresa Licenciada SOARES E LINS | B20: 3650 | C20: 11 | D20: =IFERROR(B20/SUMIFS($B$8:$B$907,$G$8:$G$907,G20),0) -> 0.019077287 | E20: =IFERROR(C20/SUMIFS($C$8:$C$907,$G$8:$G$907,G20),0) -> 0.010446344 | F20: 0 | G20: Maio/2026
A21: Empresa Licenciada SOARES E SILVA | B21: 6396 | C21: 42 | D21: =IFERROR(B21/SUMIFS($B$8:$B$907,$G$8:$G$907,G21),0) -> 0.033429678 | E21: =IFERROR(C21/SUMIFS($C$8:$C$907,$G$8:$G$907,G21),0) -> 0.03988604 | F21: 0 | G21: Maio/2026
A22: Empresa Licenciada SOUZA E SILVA | B22: 4730 | C22: 18 | D22: =IFERROR(B22/SUMIFS($B$8:$B$907,$G$8:$G$907,G22),0) -> 0.024722073 | E22: =IFERROR(C22/SUMIFS($C$8:$C$907,$G$8:$G$907,G22),0) -> 0.017094017 | F22: 0 | G22: Maio/2026
A23: Empresa Licenciada VOICENET | B23: 4782 | C23: 20 | D23: =IFERROR(B23/SUMIFS($B$8:$B$907,$G$8:$G$907,G23),0) -> 0.024993859 | E23: =IFERROR(C23/SUMIFS($C$8:$C$907,$G$8:$G$907,G23),0) -> 0.018993352 | F23: 0 | G23: Maio/2026
A24: DTEL (uso próprio) | B24: 137756 | C24: 850 | D24: =IFERROR(B24/SUMIFS($B$8:$B$907,$G$8:$G$907,G24),0) -> 0.72000293 | E24: =IFERROR(C24/SUMIFS($C$8:$C$907,$G$8:$G$907,G24),0) -> 0.80721747 | F24: 0 | G24: Maio/2026
A25: TOTAL | B25: =SUM(B17:B24) -> 191327 | C25: =SUM(C17:C24) -> 1053
A26: Empresa Licenciada DX2 | B26: 6588 | C26: 34 | D26: =IFERROR(B26/SUMIFS($B$8:$B$907,$G$8:$G$907,G26),0) -> 0.032696249 | E26: =IFERROR(C26/SUMIFS($C$8:$C$907,$G$8:$G$907,G26),0) -> 0.031192661 | F26: 0 | G26: Julho/2026
A27: Empresa Licenciada H&A | B27: 13530 | C27: 0 | D27: =IFERROR(B27/SUMIFS($B$8:$B$907,$G$8:$G$907,G27),0) -> 0.067149401 | E27: =IFERROR(C27/SUMIFS($C$8:$C$907,$G$8:$G$907,G27),0) -> 0 | F27: 0 | G27: Julho/2026
A28: Empresa Licenciada SOLON ARAUJO | B28: 14689 | C28: 47 | D28: =IFERROR(B28/SUMIFS($B$8:$B$907,$G$8:$G$907,G28),0) -> 0.072901519 | E28: =IFERROR(C28/SUMIFS($C$8:$C$907,$G$8:$G$907,G28),0) -> 0.043119266 | F28: 0 | G28: Julho/2026
A29: Empresa Licenciada SOARES E LINS | B29: 3765 | C29: 11 | D29: =IFERROR(B29/SUMIFS($B$8:$B$907,$G$8:$G$907,G29),0) -> 0.018685698 | E29: =IFERROR(C29/SUMIFS($C$8:$C$907,$G$8:$G$907,G29),0) -> 0.010091743 | F29: 0 | G29: Julho/2026
A30: Empresa Licenciada SOARES E SILVA | B30: 6568 | C30: 50 | D30: =IFERROR(B30/SUMIFS($B$8:$B$907,$G$8:$G$907,G30),0) -> 0.032596989 | E30: =IFERROR(C30/SUMIFS($C$8:$C$907,$G$8:$G$907,G30),0) -> 0.04587156 | F30: 0 | G30: Julho/2026
A31: Empresa Licenciada SOUZA E SILVA | B31: 4805 | C31: 18 | D31: =IFERROR(B31/SUMIFS($B$8:$B$907,$G$8:$G$907,G31),0) -> 0.023847219 | E31: =IFERROR(C31/SUMIFS($C$8:$C$907,$G$8:$G$907,G31),0) -> 0.016513761 | F31: 0 | G31: Julho/2026
A32: Empresa Licenciada VOICENET | B32: 4806 | C32: 24 | D32: =IFERROR(B32/SUMIFS($B$8:$B$907,$G$8:$G$907,G32),0) -> 0.023852182 | E32: =IFERROR(C32/SUMIFS($C$8:$C$907,$G$8:$G$907,G32),0) -> 0.022018349 | F32: 0 | G32: Julho/2026
A33: DTEL (uso próprio) | B33: 146740 | C33: 906 | D33: =IFERROR(B33/SUMIFS($B$8:$B$907,$G$8:$G$907,G33),0) -> 0.72827074 | E33: =IFERROR(C33/SUMIFS($C$8:$C$907,$G$8:$G$907,G33),0) -> 0.83119266 | F33: 0 | G33: Julho/2026
A34: TOTAL | B34: =SUM(B26:B33) -> 201491 | C34: =SUM(C26:C33) -> 1090
A35: RATEIO POR EMPRESA
A36: Para cada setor, o % aplicado a cada empresa vem de PARÂMETROS: % de Clientes (se critério = Clientes) ou % de Funcionários (se critério = Funcionários). O Valor de Royalty só existe se a empresa tiver % Royalty > 0% em PARÂMETROS (padrão é 0%).
A38: Setor | B38: Critério | C38: Empresa | D38: % Aplicado | E38: Custo Total do Setor | F38: Valor de Custo Rateado | G38: % Royalty | H38: Valor de Royalty | I38: Valor Total a Cobrar | J38: Mês
A39: NOC | B39: =INDEX(SETORES!$B:$B,MATCH(A39,SETORES!$A:$A,0)) -> Clientes | C39: Empresa Licenciada DX2 | D39: =IF(B39="Clientes",SUMIFS(PARÂMETROS!$D$8:$D$907,PARÂMETROS!$A$8:$A$907,C39,PARÂMETROS!$G$8:$G$907,J39),SUMIFS(PARÂMETROS!$E$8:$E$907,PARÂMETROS!$A$8:$A$907,C39,PARÂMETROS!$G$8:$G$907,J39)) -> 0.033077914 | E39: =SUMIFS(SETORES!$D:$D,SETORES!$A:$A,A39,SETORES!$F:$F,J39) -> 69943.851 | F39: =IFERROR(D39*E39,0) -> 2313.5967 | G39: =SUMIFS(PARÂMETROS!$F$8:$F$907,PARÂMETROS!$A$8:$A$907,C39,PARÂMETROS!$G$8:$G$907,J39) -> 0 | H39: =IFERROR(F39*G39,0) -> 0 | I39: =F39+H39 -> 2313.5967 | J39: Junho/2026
A40: NOC | B40: =INDEX(SETORES!$B:$B,MATCH(A40,SETORES!$A:$A,0)) -> Clientes | C40: Empresa Licenciada H&A | D40: =IF(B40="Clientes",SUMIFS(PARÂMETROS!$D$8:$D$907,PARÂMETROS!$A$8:$A$907,C40,PARÂMETROS!$G$8:$G$907,J40),SUMIFS(PARÂMETROS!$E$8:$E$907,PARÂMETROS!$A$8:$A$907,C40,PARÂMETROS!$G$8:$G$907,J40)) -> 0.068865702 | E40: =SUMIFS(SETORES!$D:$D,SETORES!$A:$A,A40,SETORES!$F:$F,J40) -> 69943.851 | F40: =IFERROR(D40*E40,0) -> 4816.7324 | G40: =SUMIFS(PARÂMETROS!$F$8:$F$907,PARÂMETROS!$A$8:$A$907,C40,PARÂMETROS!$G$8:$G$907,J40) -> 0 | H40: =IFERROR(F40*G40,0) -> 0 | I40: =F40+H40 -> 4816.7324 | J40: Junho/2026
A41: NOC | B41: =INDEX(SETORES!$B:$B,MATCH(A41,SETORES!$A:$A,0)) -> Clientes | C41: Empresa Licenciada SOLON ARAUJO | D41: =IF(B41="Clientes",SUMIFS(PARÂMETROS!$D$8:$D$907,PARÂMETROS!$A$8:$A$907,C41,PARÂMETROS!$G$8:$G$907,J41),SUMIFS(PARÂMETROS!$E$8:$E$907,PARÂMETROS!$A$8:$A$907,C41,PARÂMETROS!$G$8:$G$907,J41)) -> 0.074116083 | E41: =SUMIFS(SETORES!$D:$D,SETORES!$A:$A,A41,SETORES!$F:$F,J41) -> 69943.851 | F41: =IFERROR(D41*E41,0) -> 5183.9643 | G41: =SUMIFS(PARÂMETROS!$F$8:$F$907,PARÂMETROS!$A$8:$A$907,C41,PARÂMETROS!$G$8:$G$907,J41) -> 0 | H41: =IFERROR(F41*G41,0) -> 0 | I41: =F41+H41 -> 5183.9643 | J41: Junho/2026
A42: NOC | B42: =INDEX(SETORES!$B:$B,MATCH(A42,SETORES!$A:$A,0)) -> Clientes | C42: Empresa Licenciada SOARES E LINS | D42: =IF(B42="Clientes",SUMIFS(PARÂMETROS!$D$8:$D$907,PARÂMETROS!$A$8:$A$907,C42,PARÂMETROS!$G$8:$G$907,J42),SUMIFS(PARÂMETROS!$E$8:$E$907,PARÂMETROS!$A$8:$A$907,C42,PARÂMETROS!$G$8:$G$907,J42)) -> 0.019010177 | E42: =SUMIFS(SETORES!$D:$D,SETORES!$A:$A,A42,SETORES!$F:$F,J42) -> 69943.851 | F42: =IFERROR(D42*E42,0) -> 1329.645 | G42: =SUMIFS(PARÂMETROS!$F$8:$F$907,PARÂMETROS!$A$8:$A$907,C42,PARÂMETROS!$G$8:$G$907,J42) -> 0 | H42: =IFERROR(F42*G42,0) -> 0 | I42: =F42+H42 -> 1329.645 | J42: Junho/2026
A43: NOC | B43: =INDEX(SETORES!$B:$B,MATCH(A43,SETORES!$A:$A,0)) -> Clientes | C43: Empresa Licenciada SOARES E SILVA | D43: =IF(B43="Clientes",SUMIFS(PARÂMETROS!$D$8:$D$907,PARÂMETROS!$A$8:$A$907,C43,PARÂMETROS!$G$8:$G$907,J43),SUMIFS(PARÂMETROS!$E$8:$E$907,PARÂMETROS!$A$8:$A$907,C43,PARÂMETROS!$G$8:$G$907,J43)) -> 0.033021458 | E43: =SUMIFS(SETORES!$D:$D,SETORES!$A:$A,A43,SETORES!$F:$F,J43) -> 69943.851 | F43: =IFERROR(D43*E43,0) -> 2309.648 | G43: =SUMIFS(PARÂMETROS!$F$8:$F$907,PARÂMETROS!$A$8:$A$907,C43,PARÂMETROS!$G$8:$G$907,J43) -> 0 | H43: =IFERROR(F43*G43,0) -> 0 | I43: =F43+H43 -> 2309.648 | J43: Junho/2026
A44: NOC | B44: =INDEX(SETORES!$B:$B,MATCH(A44,SETORES!$A:$A,0)) -> Clientes | C44: Empresa Licenciada SOUZA E SILVA | D44: =IF(B44="Clientes",SUMIFS(PARÂMETROS!$D$8:$D$907,PARÂMETROS!$A$8:$A$907,C44,PARÂMETROS!$G$8:$G$907,J44),SUMIFS(PARÂMETROS!$E$8:$E$907,PARÂMETROS!$A$8:$A$907,C44,PARÂMETROS!$G$8:$G$907,J44)) -> 0.02437347 | E44: =SUMIFS(SETORES!$D:$D,SETORES!$A:$A,A44,SETORES!$F:$F,J44) -> 69943.851 | F44: =IFERROR(D44*E44,0) -> 1704.7744 | G44: =SUMIFS(PARÂMETROS!$F$8:$F$907,PARÂMETROS!$A$8:$A$907,C44,PARÂMETROS!$G$8:$G$907,J44) -> 0 | H44: =IFERROR(F44*G44,0) -> 0 | I44: =F44+H44 -> 1704.7744 | J44: Junho/2026
...

Sheet SETORES
A1: SETORES — CRITÉRIO DE RATEIO
A2: Critério de Rateio define como o custo do setor será dividido entre as empresas: por % de CLIENTES ou por % de FUNCIONÁRIOS (ver aba PARÂMETROS). Custo Unitário = Custo Total do setor dividido pelo nº total de clientes ou funcionários, conforme o critério. A coluna "Nº de Funcionários/Clientes" mostra esse divisor (a base de rateio) usado para chegar ao Custo Unitário de cada linha.
A4: Setor | B4: Critério de Rateio | C4: Justificativa | D4: Custo Total do Mês | E4: Custo Unitário | F4: Mês | G4: Nº de Funcionários/Clientes
D5: =SUMIFS('CUSTOS MENSAIS'!$F:$F,'CUSTOS MENSAIS'!$A:$A,A5,'CUSTOS MENSAIS'!$H:$H,F5) -> 0 | E5: =IFERROR(D5/IF(B5="Clientes",SUMIFS(PARÂMETROS!$B$8:$B$907,PARÂMETROS!$G$8:$G$907,F5),SUMIFS(PARÂMETROS!$C$8:$C$907,PARÂMETROS!$G$8:$G$907,F5)),0) -> 0 | G5: =IF(B5="Clientes",SUMIFS(PARÂMETROS!$B$8:$B$907,PARÂMETROS!$G$8:$G$907,F5),SUMIFS(PARÂMETROS!$C$8:$C$907,PARÂMETROS!$G$8:$G$907,F5)) -> 0
A6: NOC | B6: Clientes | C6: Infraestrutura de rede/NOC escala com o nº de clientes ativos | D6: =SUMIFS('CUSTOS MENSAIS'!$F:$F,'CUSTOS MENSAIS'!$A:$A,A6,'CUSTOS MENSAIS'!$H:$H,F6) -> 48782.853 | E6: =IFERROR(D6/IF(B6="Clientes",SUMIFS(PARÂMETROS!$B$8:$B$907,PARÂMETROS!$G$8:$G$907,F6),SUMIFS(PARÂMETROS!$C$8:$C$907,PARÂMETROS!$G$8:$G$907,F6)),0) -> 0.25497109 | F6: Maio/2026 | G6: =IF(B6="Clientes",SUMIFS(PARÂMETROS!$B$8:$B$907,PARÂMETROS!$G$8:$G$907,F6),SUMIFS(PARÂMETROS!$C$8:$C$907,PARÂMETROS!$G$8:$G$907,F6)) -> 191327
A7: RH | B7: Funcionários | C7: Recursos Humanos atende diretamente aos colaboradores | D7: =SUMIFS('CUSTOS MENSAIS'!$F:$F,'CUSTOS MENSAIS'!$A:$A,A7,'CUSTOS MENSAIS'!$H:$H,F7) -> 30023.398 | E7: =IFERROR(D7/IF(B7="Clientes",SUMIFS(PARÂMETROS!$B$8:$B$907,PARÂMETROS!$G$8:$G$907,F7),SUMIFS(PARÂMETROS!$C$8:$C$907,PARÂMETROS!$G$8:$G$907,F7)),0) -> 28.512248 | F7: Maio/2026 | G7: =IF(B7="Clientes",SUMIFS(PARÂMETROS!$B$8:$B$907,PARÂMETROS!$G$8:$G$907,F7),SUMIFS(PARÂMETROS!$C$8:$C$907,PARÂMETROS!$G$8:$G$907,F7)) -> 1053
A8: DP | B8: Funcionários | C8: Departamento Pessoal atende à folha de colaboradores | D8: =SUMIFS('CUSTOS MENSAIS'!$F:$F,'CUSTOS MENSAIS'!$A:$A,A8,'CUSTOS MENSAIS'!$H:$H,F8) -> 49826.446 | E8: =IFERROR(D8/IF(B8="Clientes",SUMIFS(PARÂMETROS!$B$8:$B$907,PARÂMETROS!$G$8:$G$907,F8),SUMIFS(PARÂMETROS!$C$8:$C$907,PARÂMETROS!$G$8:$G$907,F8)),0) -> 47.318562 | F8: Maio/2026 | G8: =IF(B8="Clientes",SUMIFS(PARÂMETROS!$B$8:$B$907,PARÂMETROS!$G$8:$G$907,F8),SUMIFS(PARÂMETROS!$C$8:$C$907,PARÂMETROS!$G$8:$G$907,F8)) -> 1053
A9: Gestão de Atendimento | B9: Clientes | C9: Atendimento administrativo e presencial de loja escala com o volume de clientes atendidos | D9: =SUMIFS('CUSTOS MENSAIS'!$F:$F,'CUSTOS MENSAIS'!$A:$A,A9,'CUSTOS MENSAIS'!$H:$H,F9) -> 20198.15 | E9: =IFERROR(D9/IF(B9="Clientes",SUMIFS(PARÂMETROS!$B$8:$B$907,PARÂMETROS!$G$8:$G$907,F9),SUMIFS(PARÂMETROS!$C$8:$C$907,PARÂMETROS!$G$8:$G$907,F9)),0) -> 0.10556874 | F9: Maio/2026 | G9: =IF(B9="Clientes",SUMIFS(PARÂMETROS!$B$8:$B$907,PARÂMETROS!$G$8:$G$907,F9),SUMIFS(PARÂMETROS!$C$8:$C$907,PARÂMETROS!$G$8:$G$907,F9)) -> 191327
A10: CAC | B10: Clientes | C10: Central de Atendimento ao Cliente atende diretamente a base de clientes de cada empresa | D10: =SUMIFS('CUSTOS MENSAIS'!$F:$F,'CUSTOS MENSAIS'!$A:$A,A10,'CUSTOS MENSAIS'!$H:$H,F10) -> 16366.893 | E10: =IFERROR(D10/IF(B10="Clientes",SUMIFS(PARÂMETROS!$B$8:$B$907,PARÂMETROS!$G$8:$G$907,F10),SUMIFS(PARÂMETROS!$C$8:$C$907,PARÂMETROS!$G$8:$G$907,F10)),0) -> 0.085544085 | F10: Maio/2026 | G10: =IF(B10="Clientes",SUMIFS(PARÂMETROS!$B$8:$B$907,PARÂMETROS!$G$8:$G$907,F10),SUMIFS(PARÂMETROS!$C$8:$C$907,PARÂMETROS!$G$8:$G$907,F10)) -> 191327
A11: Financeiro | B11: Clientes | C11: Financeiro cuida da gestão financeira e de faturamento da operação | D11: =SUMIFS('CUSTOS MENSAIS'!$F:$F,'CUSTOS MENSAIS'!$A:$A,A11,'CUSTOS MENSAIS'!$H:$H,F11) -> 71467.006 | E11: =IFERROR(D11/IF(B11="Clientes",SUMIFS(PARÂMETROS!$B$8:$B$907,PARÂMETROS!$G$8:$G$907,F11),SUMIFS(PARÂMETROS!$C$8:$C$907,PARÂMETROS!$G$8:$G$907,F11)),0) -> 0.3735333 | F11: Maio/2026 | G11: =IF(B11="Clientes",SUMIFS(PARÂMETROS!$B$8:$B$907,PARÂMETROS!$G$8:$G$907,F11),SUMIFS(PARÂMETROS!$C$8:$C$907,PARÂMETROS!$G$8:$G$907,F11)) -> 191327
A12: NRC | B12: Clientes | C12: Serviço de Atendimento ao Cliente escala com o volume de clientes atendidos | D12: =SUMIFS('CUSTOS MENSAIS'!$F:$F,'CUSTOS MENSAIS'!$A:$A,A12,'CUSTOS MENSAIS'!$H:$H,F12) -> 153380.8 | E12: =IFERROR(D12/IF(B12="Clientes",SUMIFS(PARÂMETROS!$B$8:$B$907,PARÂMETROS!$G$8:$G$907,F12),SUMIFS(PARÂMETROS!$C$8:$C$907,PARÂMETROS!$G$8:$G$907,F12)),0) -> 0.80166833 | F12: Maio/2026 | G12: =IF(B12="Clientes",SUMIFS(PARÂMETROS!$B$8:$B$907,PARÂMETROS!$G$8:$G$907,F12),SUMIFS(PARÂMETROS!$C$8:$C$907,PARÂMETROS!$G$8:$G$907,F12)) -> 191327
A13: Cobrança | B13: Clientes | C13: Cobrança atua sobre a carteira de clientes inadimplentes de cada empresa | D13: =SUMIFS('CUSTOS MENSAIS'!$F:$F,'CUSTOS MENSAIS'!$A:$A,A13,'CUSTOS MENSAIS'!$H:$H,F13) -> 43385.322 | E13: =IFERROR(D13/IF(B13="Clientes",SUMIFS(PARÂMETROS!$B$8:$B$907,PARÂMETROS!$G$8:$G$907,F13),SUMIFS(PARÂMETROS!$C$8:$C$907,PARÂMETROS!$G$8:$G$907,F13)),0) -> 0.22676006 | F13: Maio/2026 | G13: =IF(B13="Clientes",SUMIFS(PARÂMETROS!$B$8:$B$907,PARÂMETROS!$G$8:$G$907,F13),SUMIFS(PARÂMETROS!$C$8:$C$907,PARÂMETROS!$G$8:$G$907,F13)) -> 191327
A14: Retenção | B14: Clientes | C14: Retenção atua sobre a base de clientes de cada empresa para evitar cancelamento | D14: =SUMIFS('CUSTOS MENSAIS'!$F:$F,'CUSTOS MENSAIS'!$A:$A,A14,'CUSTOS MENSAIS'!$H:$H,F14) -> 37959.883 | E14: =IFERROR(D14/IF(B14="Clientes",SUMIFS(PARÂMETROS!$B$8:$B$907,PARÂMETROS!$G$8:$G$907,F14),SUMIFS(PARÂMETROS!$C$8:$C$907,PARÂMETROS!$G$8:$G$907,F14)),0) -> 0.19840317 | F14: Maio/2026 | G14: =IF(B14="Clientes",SUMIFS(PARÂMETROS!$B$8:$B$907,PARÂMETROS!$G$8:$G$907,F14),SUMIFS(PARÂMETROS!$C$8:$C$907,PARÂMETROS!$G$8:$G$907,F14)) -> 191327
A15: Contabilidade | B15: Clientes | C15: Contabilidade realiza a escrituração fiscal e contábil da operação | D15: =SUMIFS('CUSTOS MENSAIS'!$F:$F,'CUSTOS MENSAIS'!$A:$A,A15,'CUSTOS MENSAIS'!$H:$H,F15) -> 27353.28 | E15: =IFERROR(D15/IF(B15="Clientes",SUMIFS(PARÂMETROS!$B$8:$B$907,PARÂMETROS!$G$8:$G$907,F15),SUMIFS(PARÂMETROS!$C$8:$C$907,PARÂMETROS!$G$8:$G$907,F15)),0) -> 0.14296612 | F15: Maio/2026 | G15: =IF(B15="Clientes",SUMIFS(PARÂMETROS!$B$8:$B$907,PARÂMETROS!$G$8:$G$907,F15),SUMIFS(PARÂMETROS!$C$8:$C$907,PARÂMETROS!$G$8:$G$907,F15)) -> 191327
A16: Controladoria | B16: Clientes | C16: Controladoria acompanha os indicadores financeiros da operação | D16: =SUMIFS('CUSTOS MENSAIS'!$F:$F,'CUSTOS MENSAIS'!$A:$A,A16,'CUSTOS MENSAIS'!$H:$H,F16) -> 18180.292 | E16: =IFERROR(D16/IF(B16="Clientes",SUMIFS(PARÂMETROS!$B$8:$B$907,PARÂMETROS!$G$8:$G$907,F16),SUMIFS(PARÂMETROS!$C$8:$C$907,PARÂMETROS!$G$8:$G$907,F16)),0) -> 0.095022093 | F16: Maio/2026 | G16: =IF(B16="Clientes",SUMIFS(PARÂMETROS!$B$8:$B$907,PARÂMETROS!$G$8:$G$907,F16),SUMIFS(PARÂMETROS!$C$8:$C$907,PARÂMETROS!$G$8:$G$907,F16)) -> 191327
A17: Diretoria Operacional | B17: Clientes | C17: Diretoria Operacional coordena a operação das áreas técnicas e de atendimento | D17: =SUMIFS('CUSTOS MENSAIS'!$F:$F,'CUSTOS MENSAIS'!$A:$A,A17,'CUSTOS MENSAIS'!$H:$H,F17) -> 27798.627 | E17: =IFERROR(D17/IF(B17="Clientes",SUMIFS(PARÂMETROS!$B$8:$B$907,PARÂMETROS!$G$8:$G$907,F17),SUMIFS(PARÂMETROS!$C$8:$C$907,PARÂMETROS!$G$8:$G$907,F17)),0) -> 0.1452938 | F17: Maio/2026 | G17: =IF(B17="Clientes",SUMIFS(PARÂMETROS!$B$8:$B$907,PARÂMETROS!$G$8:$G$907,F17),SUMIFS(PARÂMETROS!$C$8:$C$907,PARÂMETROS!$G$8:$G$907,F17)) -> 191327
... A39: Diretoria Adm | B39: Clientes | C39: Diretoria Administrativa realiza a gestão administrativa executiva da operação | D39: =SUMIFS('CUSTOS MENSAIS'!$F:$F,'CUSTOS MENSAIS'!$A:$A,A39,'CUSTOS MENSAIS'!$H:$H,F39) -> 29568.366 | E39: =IFERROR(D39/IF(B39="Clientes",SUMIFS(PARÂMETROS!$B$8:$B$907,PARÂMETROS!$G$8:$G$907,F39),SUMIFS(PARÂMETROS!$C$8:$C$907,PARÂMETROS!$G$8:$G$907,F39)),0) -> 0.15454361 | F39: Maio/2026 | G39: =IF(B39="Clientes",SUMIFS(PARÂMETROS!$B$8:$B$907,PARÂMETROS!$G$8:$G$907,F39),SUMIFS(PARÂMETROS!$C$8:$C$907,PARÂMETROS!$G$8:$G$907,F39)) -> 191327
A40: Cozinha | B40: Funcionários | C40: Cozinha prepara as refeições dos colaboradores | D40: =SUMIFS('CUSTOS MENSAIS'!$F:$F,'CUSTOS MENSAIS'!$A:$A,A40,'CUSTOS MENSAIS'!$H:$H,F40) -> 28357.989 | E40: =IFERROR(D40/G40,0) -> 33.36234 | F40: Maio/2026 | G40: =SUMIFS(PARÂMETROS!$C$8:$C$907,PARÂMETROS!$G$8:$G$907,F40,PARÂMETROS!$A$8:$A$907,"DTEL (uso próprio)") -> 850
A41: TOTAL GERAL — Maio/2026 | D41: =SUM(D5:D40)+D114+D117+D120+D123 -> 2151966.9
A42: NOC | B42: Clientes | C42: Infraestrutura de rede/NOC escala com o nº de clientes ativos | D42: =SUMIFS('CUSTOS MENSAIS'!$F:$F,'CUSTOS MENSAIS'!$A:$A,A42,'CUSTOS MENSAIS'!$H:$H,F42) -> 69943.851 | E42: =IFERROR(D42/IF(B42="Clientes",SUMIFS(PARÂMETROS!$B$8:$B$907,PARÂMETROS!$G$8:$G$907,F42),SUMIFS(PARÂMETROS!$C$8:$C$907,PARÂMETROS!$G$8:$G$907,F42)),0) -> 0.35897544 | F42: Junho/2026 | G42: =IF(B42="Clientes",SUMIFS(PARÂMETROS!$B$8:$B$907,PARÂMETROS!$G$8:$G$907,F42),SUMIFS(PARÂMETROS!$C$8:$C$907,PARÂMETROS!$G$8:$G$907,F42)) -> 194843
A43: RH | B43: Funcionários | C43: Recursos Humanos atende diretamente aos colaboradores | D43: =SUMIFS('CUSTOS MENSAIS'!$F:$F,'CUSTOS MENSAIS'!$A:$A,A43,'CUSTOS MENSAIS'!$H:$H,F43) -> 36047.874 | E43: =IFERROR(D43/IF(B43="Clientes",SUMIFS(PARÂMETROS!$B$8:$B$907,PARÂMETROS!$G$8:$G$907,F43),SUMIFS(PARÂMETROS!$C$8:$C$907,PARÂMETROS!$G$8:$G$907,F43)),0) -> 34.364037 | F43: Junho/2026 | G43: =IF(B43="Clientes",SUMIFS(PARÂMETROS!$B$8:$B$907,PARÂMETROS!$G$8:$G$907,F43),SUMIFS(PARÂMETROS!$C$8:$C$907,PARÂMETROS!$G$8:$G$907,F43)) -> 1049
A44: DP | B44: Funcionários | C44: Departamento Pessoal atende à folha de colaboradores | D44: =SUMIFS('CUSTOS MENSAIS'!$F:$F,'CUSTOS MENSAIS'!$A:$A,A44,'CUSTOS MENSAIS'!$H:$H,F44) -> 54615.876 | E44: =IFERROR(D44/IF(B44="Clientes",SUMIFS(PARÂMETROS!$B$8:$B$907,PARÂMETROS!$G$8:$G$907,F44),SUMIFS(PARÂMETROS!$C$8:$C$907,PARÂMETROS!$G$8:$G$907,F44)),0) -> 52.064705 | F44: Junho/2026 | G44: =IF(B44="Clientes",SUMIFS(PARÂMETROS!$B$8:$B$907,PARÂMETROS!$G$8:$G$907,F44),SUMIFS(PARÂMETROS!$C$8:$C$907,PARÂMETROS!$G$8:$G$907,F44)) -> 1049
A45: Gestão de Atendimento | B45: Clientes | C45: Atendimento administrativo e presencial de loja escala com o volume de clientes atendidos | D45: =SUMIFS('CUSTOS MENSAIS'!$F:$F,'CUSTOS MENSAIS'!$A:$A,A45,'CUSTOS MENSAIS'!$H:$H,F45) -> 23728.993 | E45: =IFERROR(D45/IF(B45="Clientes",SUMIFS(PARÂMETROS!$B$8:$B$907,PARÂMETROS!$G$8:$G$907,F45),SUMIFS(PARÂMETROS!$C$8:$C$907,PARÂMETROS!$G$8:$G$907,F45)),0) -> 0.1217852 | F45: Junho/2026 | G45: =IF(B45="Clientes",SUMIFS(PARÂMETROS!$B$8:$B$907,PARÂMETROS!$G$8:$G$907,F45),SUMIFS(PARÂMETROS!$C$8:$C$907,PARÂMETROS!$G$8:$G$907,F45)) -> 194843
A46: CAC | B46: Clientes | C46: Central de Atendimento ao Cliente atende diretamente a base de clientes de cada empresa | D46: =SUMIFS('CUSTOS MENSAIS'!$F:$F,'CUSTOS MENSAIS'!$A:$A,A46,'CUSTOS MENSAIS'!$H:$H,F46) -> 17219.469 | E46: =IFERROR(D46/IF(B46="Clientes",SUMIFS(PARÂMETROS!$B$8:$B$907,PARÂMETROS!$G$8:$G$907,F46),SUMIFS(PARÂMETROS!$C$8:$C$907,PARÂMETROS!$G$8:$G$907,F46)),0) -> 0.088376123 | F46: Junho/2026 | G46: =IF(B46="Clientes",SUMIFS(PARÂMETROS!$B$8:$B$907,PARÂMETROS!$G$8:$G$907,F46),SUMIFS(PARÂMETROS!$C$8:$C$907,PARÂMETROS!$G$8:$G$907,F46)) -> 194843
A47: Financeiro | B47: Clientes | C47: Financeiro cuida da gestão financeira e de faturamento da operação | D47: =SUMIFS('CUSTOS MENSAIS'!$F:$F,'CUSTOS MENSAIS'!$A:$A,A47,'CUSTOS MENSAIS'!$H:$H,F47) -> 70630.626 | E47: =IFERROR(D47/IF(B47="Clientes",SUMIFS(PARÂMETROS!$B$8:$B$907,PARÂMETROS!$G$8:$G$907,F47),SUMIFS(PARÂMETROS!$C$8:$C$907,PARÂMETROS!$G$8:$G$907,F47)),0) -> 0.3625002 | F47: Junho/2026 | G47: =IF(B47="Clientes",SUMIFS(PARÂMETROS!$B$8:$B$907,PARÂMETROS!$G$8:$G$907,F47),SUMIFS(PARÂMETROS!$C$8:$C$907,PARÂMETROS!$G$8:$G$907,F47)) -> 194843
A48: NRC | B48: Clientes | C48: Serviço de Atendimento ao Cliente escala com o volume de clientes atendidos | D48: =SUMIFS('CUSTOS MENSAIS'!$F:$F,'CUSTOS MENSAIS'!$A:$A,A48,'CUSTOS MENSAIS'!$H:$H,F48) -> 173281.41 | E48: =IFERROR(D48/IF(B48="Clientes",SUMIFS(PARÂMETROS!$B$8:$B$907,PARÂMETROS!$G$8:$G$907,F48),SUMIFS(PARÂMETROS!$C$8:$C$907,PARÂMETROS!$G$8:$G$907,F48)),0) -> 0.88933867 | F48: Junho/2026 | G48: =IF(B48="Clientes",SUMIFS(PARÂMETROS!$B$8:$B$907,PARÂMETROS!$G$8:$G$907,F48),SUMIFS(PARÂMETROS!$C$8:$C$907,PARÂMETROS!$G$8:$G$907,F48)) -> 194843
A49: Cobrança | B49: Clientes | C49: Cobrança atua sobre a carteira de clientes inadimplentes de cada empresa | D49: =SUMIFS('CUSTOS MENSAIS'!$F:$F,'CUSTOS MENSAIS'!$A:$A,A49,'CUSTOS MENSAIS'!$H:$H,F49) -> 42678.536 | E49: =IFERROR(D49/IF(B49="Clientes",SUMIFS(PARÂMETROS!$B$8:$B$907,PARÂMETROS!$G$8:$G$907,F49),SUMIFS(PARÂMETROS!$C$8:$C$907,PARÂMETROS!$G$8:$G$907,F49)),0) -> 0.21904064 | F49: Junho/2026 | G49: =IF(B49="Clientes",SUMIFS(PARÂMETROS!$B$8:$B$907,PARÂMETROS!$G$8:$G$907,F49),SUMIFS(PARÂMETROS!$C$8:$C$907,PARÂMETROS!$G$8:$G$907,F49)) -> 194843
A50: Retenção | B50: Clientes | C50: Retenção atua sobre a base de clientes de cada empresa para evitar cancelamento | D50: =SUMIFS('CUSTOS MENSAIS'!$F:$F,'CUSTOS MENSAIS'!$A:$A,A50,'CUSTOS MENSAIS'!$H:$H,F50) -> 51023.149 | E50: =IFERROR(D50/IF(B50="Clientes",SUMIFS(PARÂMETROS!$B$8:$B$907,PARÂMETROS!$G$8:$G$907,F50),SUMIFS(PARÂMETROS!$C$8:$C$907,PARÂMETROS!$G$8:$G$907,F50)),0) -> 0.26186801 | F50: Junho/2026 | G50: =IF(B50="Clientes",SUMIFS(PARÂMETROS!$B$8:$B$907,PARÂMETROS!$G$8:$G$907,F50),SUMIFS(PARÂMETROS!$C$8:$C$907,PARÂMETROS!$G$8:$G$907,F50)) -> 194843
A51: Contabilidade | B51: Clientes | C51: Contabilidade realiza a escrituração fiscal e contábil da operação | D51: =SUMIFS('CUSTOS MENSAIS'!$F:$F,'CUSTOS MENSAIS'!$A:$A,A51,'CUSTOS MENSAIS'!$H:$H,F51) -> 38110.164 | E51: =IFERROR(D51/IF(B51="Clientes",SUMIFS(PARÂMETROS!$B$8:$B$907,PARÂMETROS!$G$8:$G$907,F51),SUMIFS(PARÂMETROS!$C$8:$C$907,PARÂMETROS!$G$8:$G$907,F51)),0) -> 0.19559422 | F51: Junho/2026 | G51: =IF(B51="Clientes",SUMIFS(PARÂMETROS!$B$8:$B$907,PARÂMETROS!$G$8:$G$907,F51),SUMIFS(PARÂMETROS!$C$8:$C$907,PARÂMETROS!$G$8:$G$907,F51)) -> 194843
A52: Controladoria | B52: Clientes | C52: Controladoria acompanha os indicadores financeiros da operação | D52: =SUMIFS('CUSTOS MENSAIS'!$F:$F,'CUSTOS MENSAIS'!$A:$A,A52,'CUSTOS MENSAIS'!$H:$H,F52) -> 18198.009 | E52: =IFERROR(D52/IF(B52="Clientes",SUMIFS(PARÂMETROS!$B$8:$B$907,PARÂMETROS!$G$8:$G$907,F52),SUMIFS(PARÂMETROS!$C$8:$C$907,PARÂMETROS!$G$8:$G$907,F52)),0) -> 0.093398318 | F52: Junho/2026 | G52: =IF(B52="Clientes",SUMIFS(PARÂMETROS!$B$8:$B$907,PARÂMETROS!$G$8:$G$907,F52),SUMIFS(PARÂMETROS!$C$8:$C$907,PARÂMETROS!$G$8:$G$907,F52)) -> 194843
A53: Diretoria Operacional | B53: Clientes | C53: Diretoria Operacional coordena a operação das áreas técnicas e de atendimento | D53: =SUMIFS('CUSTOS MENSAIS'!$F:$F,'CUSTOS MENSAIS'!$A:$A,A53,'CUSTOS MENSAIS'!$H:$H,F53) -> 28599.528 | E53: =IFERROR(D53/IF(B53="Clientes",SUMIFS(PARÂMETROS!$B$8:$B$907,PARÂMETROS!$G$8:$G$907,F53),SUMIFS(PARÂMETROS!$C$8:$C$907,PARÂMETROS!$G$8:$G$907,F53)),0) -> 0.14678242 | F53: Junho/2026 | G53: =IF(B53="Clientes",SUMIFS(PARÂMETROS!$B$8:$B$907,PARÂMETROS!$G$8:$G$907,F53),SUMIFS(PARÂMETROS!$C$8:$C$907,PARÂMETROS!$G$8:$G$907,F53)) -> 194843
... A64: Suporte da Central | B64: Clientes | C64: Suporte da Central dá suporte técnico à central de atendimento | D64: =SUMIFS('CUSTOS MENSAIS'!$F:$F,'CUSTOS MENSAIS'!$A:$A,A64,'CUSTOS MENSAIS'!$H:$H,F64) -> 126953.68 | E64: =IFERROR(D64/IF(B64="Clientes",SUMIFS(PARÂMETROS!$B$8:$B$907,PARÂMETROS!$G$8:$G$907,F64),SUMIFS(PARÂMETROS!$C$8:$C$907,PARÂMETROS!$G$8:$G$907,F64)),0) -> 0.65156913 | F64: Junho/2026 | G64: =IF(B64="Clientes",SUMIFS(PARÂMETROS!$B$8:$B$907,PARÂMETROS!$G$8:$G$907,F64),SUMIFS(PARÂMETROS!$C$8:$C$907,PARÂMETROS!$G$8:$G$907,F64)) -> 194843
A65: Comercial Corporativo | B65: Vendas | C65: Comercial Corporativo realiza vendas para clientes corporativos | D65: =SUMIFS('CUSTOS MENSAIS'!$F:$F,'CUSTOS MENSAIS'!$A:$A,A65,'CUSTOS MENSAIS'!$H:$H,F65) -> 143669.77 | E65: =IFERROR(D65/G65,0) -> 997.70672 | F65: Junho/2026 | G65: 144
A66: Administrativo | B66: Funcionários | C66: Administrativo reúne os softwares e sistemas corporativos usados pela operação | D66: =SUMIFS('CUSTOS MENSAIS'!$F:$F,'CUSTOS MENSAIS'!$A:$A,A66,'CUSTOS MENSAIS'!$H:$H,F66) -> 23776.15 | E66: =IFERROR(D66/IF(B66="Clientes",SUMIFS(PARÂMETROS!$B$8:$B$907,PARÂMETROS!$G$8:$G$907,F66),SUMIFS(PARÂMETROS!$C$8:$C$907,PARÂMETROS!$G$8:$G$907,F66)),0) -> 22.665539 | F66: Junho/2026 | G66: =IF(B66="Clientes",SUMIFS(PARÂMETROS!$B$8:$B$907,PARÂMETROS!$G$8:$G$907,F66),SUMIFS(PARÂMETROS!$C$8:$C$907,PARÂMETROS!$G$8:$G$907,F66)) -> 1049
A67: Qualidade | B67: Clientes | C67: Área de Qualidade garante o padrão de atendimento e dos serviços prestados aos clientes | D67: =SUMIFS('CUSTOS MENSAIS'!$F:$F,'CUSTOS MENSAIS'!$A:$A,A67,'CUSTOS MENSAIS'!$H:$H,F67) -> 35036.851 | E67: =IFERROR(D67/IF(B67="Clientes",SUMIFS(PARÂMETROS!$B$8:$B$907,PARÂMETROS!$G$8:$G$907,F67),SUMIFS(PARÂMETROS!$C$8:$C$907,PARÂMETROS!$G$8:$G$907,F67)),0) -> 0.17982094 | F67: Junho/2026 | G67: =IF(B67="Clientes",SUMIFS(PARÂMETROS!$B$8:$B$907,PARÂMETROS!$G$8:$G$907,F67),SUMIFS(PARÂMETROS!$C$8:$C$907,PARÂMETROS!$G$8:$G$907,F67)) -> 194843
A68: Jurídico | B68: Clientes | C68: Jurídico atua nas demandas legais e contratuais da operação | D68: =SUMIFS('CUSTOS MENSAIS'!$F:$F,'CUSTOS MENSAIS'!$A:$A,A68,'CUSTOS MENSAIS'!$H:$H,F68) -> 15557.95 | E68: =IFERROR(D68/IF(B68="Clientes",SUMIFS(PARÂMETROS!$B$8:$B$907,PARÂMETROS!$G$8:$G$907,F68),SUMIFS(PARÂMETROS!$C$8:$C$907,PARÂMETROS!$G$8:$G$907,F68)),0) -> 0.079848647 | F68: Junho/2026 | G68: =IF(B68="Clientes",SUMIFS(PARÂMETROS!$B$8:$B$907,PARÂMETROS!$G$8:$G$907,F68),SUMIFS(PARÂMETROS!$C$8:$C$907,PARÂMETROS!$G$8:$G$907,F68)) -> 194843
A69: Marketing | B69: Clientes | C69: Marketing atua na captação, retenção e comunicação com a base de clientes | D69: =SUMIFS('CUSTOS MENSAIS'!$F:$F,'CUSTOS MENSAIS'!$A:$A,A69,'CUSTOS MENSAIS'!$H:$H,F69) -> 57175.147 | E69: =IFERROR(D69/IF(B69="Clientes",SUMIFS(PARÂMETROS!$B$8:$B$907,PARÂMETROS!$G$8:$G$907,F69),SUMIFS(PARÂMETROS!$C$8:$C$907,PARÂMETROS!$G$8:$G$907,F69)),0) -> 0.29344214 | F69: Junho/2026 | G69: =IF(B69="Clientes",SUMIFS(PARÂMETROS!$B$8:$B$907,PARÂMETROS!$G$8:$G$907,F69),SUMIFS(PARÂMETROS!$C$8:$C$907,PARÂMETROS!$G$8:$G$907,F69)) -> 194843
A70: TIC | B70: Clientes | C70: TIC dá suporte de infraestrutura de tecnologia à operação voltada aos clientes | D70: =SUMIFS('CUSTOS MENSAIS'!$F:$F,'CUSTOS MENSAIS'!$A:$A,A70,'CUSTOS MENSAIS'!$H:$H,F70) -> 32275.313 | E70: =IFERROR(D70/IF(B70="Clientes",SUMIFS(PARÂMETROS!$B$8:$B$907,PARÂMETROS!$G$8:$G$907,F70),SUMIFS(PARÂMETROS!$C$8:$C$907,PARÂMETROS!$G$8:$G$907,F70)),0) -> 0.16564779 | F70: Junho/2026 | G70: =IF(B70="Clientes",SUMIFS(PARÂMETROS!$B$8:$B$907,PARÂMETROS!$G$8:$G$907,F70),SUMIFS(PARÂMETROS!$C$8:$C$907,PARÂMETROS!$G$8:$G$907,F70)) -> 194843
A71: COE | B71: Clientes | C71: Centro de Operações Especiais (COE) trata despacho e demandas operacionais ligadas à base de clientes | D71: =SUMIFS('CUSTOS MENSAIS'!$F:$F,'CUSTOS MENSAIS'!$A:$A,A71,'CUSTOS MENSAIS'!$H:$H,F71) -> 94839.632 | E71: =IFERROR(D71/IF(B71="Clientes",SUMIFS(PARÂMETROS!$B$8:$B$907,PARÂMETROS!$G$8:$G$907,F71),SUMIFS(PARÂMETROS!$C$8:$C$907,PARÂMETROS!$G$8:$G$907,F71)),0) -> 0.48674898 | F71: Junho/2026 | G71: =IF(B71="Clientes",SUMIFS(PARÂMETROS!$B$8:$B$907,PARÂMETROS!$G$8:$G$907,F71),SUMIFS(PARÂMETROS!$C$8:$C$907,PARÂMETROS!$G$8:$G$907,F71)) -> 194843
A72: Fique Móvel | B72: Clientes | C72: Fique Móvel é equipe de vendas que atua diretamente na captação de clientes | D72: =SUMIFS('CUSTOS MENSAIS'!$F:$F,'CUSTOS MENSAIS'!$A:$A,A72,'CUSTOS MENSAIS'!$H:$H,F72) -> 13388.393 | E72: =IFERROR(D72/IF(B72="Clientes",SUMIFS(PARÂMETROS!$B$8:$B$907,PARÂMETROS!$G$8:$G$907,F72),SUMIFS(PARÂMETROS!$C$8:$C$907,PARÂMETROS!$G$8:$G$907,F72)),0) -> 0.068713748 | F72: Junho/2026 | G72: =IF(B72="Clientes",SUMIFS(PARÂMETROS!$B$8:$B$907,PARÂMETROS!$G$8:$G$907,F72),SUMIFS(PARÂMETROS!$C$8:$C$907,PARÂMETROS!$G$8:$G$907,F72)) -> 194843
...

Sheet CUSTOS MENSAIS
A1: CUSTOS MENSAIS — POR SETOR
A2: Preencha Quantidade e Valor Unitário (azul) — o Total do Mês é calculado automaticamente (Quantidade × Valor Unitário). Se só existir um valor total (sem quantidade/preço unitário), use Quantidade = 1 e Valor Unitário = o valor total. Linha 5 é um EXEMPLO — substitua pelos valores reais.
A4: Setor | B4: Categoria | C4: Descrição do Custo | D4: Quantidade | E4: Valor Unitário | F4: Total do Mês | G4: Critério de Rateio | H4: Mês
A5: Administrativo | B5: Custo Fixo | C5: Licença Google Workspace | D5: 1 | E5: 21454 | F5: =IFERROR(D5*E5,0) -> 21454 | G5: =INDEX(SETORES!$B:$B,MATCH(A5,SETORES!$A:$A,0)) -> Funcionários | H5: Agosto/2026
A6: Administrativo | B6: Custo Variável | C6: Rescisões trabalhistas | F6: =IFERROR(D6*E6,0) -> 0 | G6: =INDEX(SETORES!$B:$B,MATCH(A6,SETORES!$A:$A,0)) -> Funcionários | H6: Agosto/2026
A7: Administrativo | B7: Custo Fixo | C7: Sistema de assinatura eletronica (autentique) (TIC) | D7: 1 | E7: 99 | F7: =IFERROR(D7*E7,0) -> 99 | G7: =INDEX(SETORES!$B:$B,MATCH(A7,SETORES!$A:$A,0)) -> Funcionários | H7: Agosto/2026
A8: Administrativo | B8: Custo Fixo | C8: Software de sistema eletronico de alarme (administrativo) | F8: =IFERROR(D8*E8,0) -> 0 | G8: =INDEX(SETORES!$B:$B,MATCH(A8,SETORES!$A:$A,0)) -> Funcionários | H8: Agosto/2026
A9: Administrativo | B9: Custo Fixo | C9: Software Power BI Dynamics (f001796) | D9: 1 | E9: 1787.09 | F9: =IFERROR(D9*E9,0) -> 1787.09 | G9: =INDEX(SETORES!$B:$B,MATCH(A9,SETORES!$A:$A,0)) -> Funcionários | H9: Agosto/2026
A10: Backoffice Comercial Varejo | B10: Custo Fixo | C10: Água e esgoto (rateio) | F10: =IFERROR(D10*E10,0) -> 0 | G10: =INDEX(SETORES!$B:$B,MATCH(A10,SETORES!$A:$A,0)) -> Clientes | H10: Agosto/2026
A11: Backoffice Comercial Varejo | B11: Custo Fixo | C11: Chip móvel corporativo | D11: 1 | E11: 30 | F11: =IFERROR(D11*E11,0) -> 30 | G11: =INDEX(SETORES!$B:$B,MATCH(A11,SETORES!$A:$A,0)) -> Clientes | H11: Agosto/2026
A12: Backoffice Comercial Varejo | B12: Custo Fixo | C12: Custo de gestão administrativa (rateado — Renata Thaysa dos Santos Cunha) | D12: 1 | E12: 582.06 | F12: =IFERROR(D12*E12,0) -> 582.06 | G12: =INDEX(SETORES!$B:$B,MATCH(A12,SETORES!$A:$A,0)) -> Clientes | H12: Agosto/2026
A13: Backoffice Comercial Varejo | B13: Custo Fixo | C13: Despesas com DP | D13: 2 | E13: 52.09 | F13: =IFERROR(D13*E13,0) -> 104.18 | G13: Funcionários | H13: Agosto/2026
A14: Backoffice Comercial Varejo | B14: Custo Fixo | C14: Despesas com RH | D14: 2 | E14: 32.55 | F14: =IFERROR(D14*E14,0) -> 65.1 | G14: Funcionários | H14: Agosto/2026
A15: Backoffice Comercial Varejo | B15: Custo Fixo | C15: Despesas com SST | D15: 2 | E15: 52.35 | F15: =IFERROR(D15*E15,0) -> 104.7 | G15: Funcionários | H15: Agosto/2026
A16: Backoffice Comercial Varejo | B16: Custo Fixo | C16: Energia elétrica (rateio) | F16: =IFERROR(D16*E16,0) -> 0 | G16: =INDEX(SETORES!$B:$B,MATCH(A16,SETORES!$A:$A,0)) -> Clientes | H16: Agosto/2026
A17: Backoffice Comercial Varejo | B17: Custo Fixo | C17: Folha de pagamento (salários) | D17: 1 | E17: 7220.72 | F17: =IFERROR(D17*E17,0) -> 7220.72 | G17: =INDEX(SETORES!$B:$B,MATCH(A17,SETORES!$A:$A,0)) -> Clientes | H17: Agosto/2026
A18: Backoffice Comercial Varejo | B18: Custo Fixo | C18: Gympass | F18: =IFERROR(D18*E18,0) -> 0 | G18: =INDEX(SETORES!$B:$B,MATCH(A18,SETORES!$A:$A,0)) -> Clientes | H18: Agosto/2026
A19: Backoffice Comercial Varejo | B19: Custo Fixo | C19: Instalações - corredores e alojamentos (rateio) | D19: 1 | E19: 38.77 | F19: =IFERROR(D19*E19,0) -> 38.77 | G19: =INDEX(SETORES!$B:$B,MATCH(A19,SETORES!$A:$A,0)) -> Clientes | H19: Agosto/2026
A20: Backoffice Comercial Varejo | B20: Custo Fixo | C20: Licença de e-mail corporativo | D20: 2 | E20: 50 | F20: =IFERROR(D20*E20,0) -> 100 | G20: =INDEX(SETORES!$B:$B,MATCH(A20,SETORES!$A:$A,0)) -> Clientes | H20: Agosto/2026
A21: Backoffice Comercial Varejo | B21: Custo Fixo | C21: Stargrid | D21: 2 | E21: 1.87 | F21: =IFERROR(D21*E21,0) -> 3.74 | G21: =INDEX(SETORES!$B:$B,MATCH(A21,SETORES!$A:$A,0)) -> Clientes | H21: Agosto/2026
A22: CAC | B22: Custo Fixo | C22: Água e esgoto (rateio) | F22: =IFERROR(D22*E22,0) -> 0 | G22: =INDEX(SETORES!$B:$B,MATCH(A22,SETORES!$A:$A,0)) -> Clientes | H22: Agosto/2026
A23: CAC | B23: Custo Fixo | C23: Chip móvel corporativo | D23: 1 | E23: 30 | F23: =IFERROR(D23*E23,0) -> 30 | G23: =INDEX(SETORES!$B:$B,MATCH(A23,SETORES!$A:$A,0)) -> Clientes | H23: Agosto/2026
A24: CAC | B24: Custo Fixo | C24: Custo de gestão administrativa (rateado — Renata Thaysa dos Santos Cunha) | D24: 1 | E24: 1455.14 | F24: =IFERROR(D24*E24,0) -> 1455.14 | G24: =INDEX(SETORES!$B:$B,MATCH(A24,SETORES!$A:$A,0)) -> Clientes | H24: Agosto/2026
A25: CAC | B25: Custo Fixo | C25: Despesas com DP | D25: 5 | E25: 52.09 | F25: =IFERROR(D25*E25,0) -> 260.45 | G25: Funcionários | H25: Agosto/2026
A26: CAC | B26: Custo Fixo | C26: Despesas com RH | D26: 5 | E26: 32.55 | F26: =IFERROR(D26*E26,0) -> 162.75 | G26: Funcionários | H26: Agosto/2026
A27: CAC | B27: Custo Fixo | C27: Despesas com SST | D27: 5 | E27: 52.35 | F27: =IFERROR(D27*E27,0) -> 261.75 | G27: Funcionários | H27: Agosto/2026
A28: CAC | B28: Custo Fixo | C28: Energia elétrica (rateio) | F28: =IFERROR(D28*E28,0) -> 0 | G28: =INDEX(SETORES!$B:$B,MATCH(A28,SETORES!$A:$A,0)) -> Clientes | H28: Agosto/2026
A29: CAC | B29: Custo Variável | C29: Exames médicos | F29: =IFERROR(D29*E29,0) -> 0 | G29: =INDEX(SETORES!$B:$B,MATCH(A29,SETORES!$A:$A,0)) -> Clientes | H29: Agosto/2026
A30: CAC | B30: Custo Variável | C30: Fardamento novo | F30: =IFERROR(D30*E30,0) -> 0 | G30: =INDEX(SETORES!$B:$B,MATCH(A30,SETORES!$A:$A,0)) -> Clientes | H30: Agosto/2026
A31: CAC | B31: Custo Variável | C31: Fardamento substituição | F31: =IFERROR(D31*E31,0) -> 0 | G31: =INDEX(SETORES!$B:$B,MATCH(A31,SETORES!$A:$A,0)) -> Clientes | H31: Agosto/2026
A32: CAC | B32: Custo Fixo | C32: Folha de pagamento (salários) | D32: 1 | E32: 21051.01 | F32: =IFERROR(D32*E32,0) -> 21051.01 | G32: =INDEX(SETORES!$B:$B,MATCH(A32,SETORES!$A:$A,0)) -> Clientes | H32: Agosto/2026
A33: CAC | B33: Custo Fixo | C33: Gympass | F33: =IFERROR(D33*E33,0) -> 0 | G33: =INDEX(SETORES!$B:$B,MATCH(A33,SETORES!$A:$A,0)) -> Clientes | H33: Agosto/2026
A34: CAC | B34: Custo Fixo | C34: Instalações - corredores e alojamentos (rateio) | D34: 1 | E34: 96.93 | F34: =IFERROR(D34*E34,0) -> 96.93 | G34: =INDEX(SETORES!$B:$B,MATCH(A34,SETORES!$A:$A,0)) -> Clientes | H34: Agosto/2026
A35: CAC | B35: Custo Fixo | C35: Licença de e-mail corporativo | D35: 5 | E35: 50 | F35: =IFERROR(D35*E35,0) -> 250 | G35: =INDEX(SETORES!$B:$B,MATCH(A35,SETORES!$A:$A,0)) -> Clientes | H35: Agosto/2026
A36: CAC | B36: Custo Fixo | C36: Material de escritório (suprimentos de informática) | F36: =IFERROR(D36*E36,0) -> 0 | G36: =INDEX(SETORES!$B:$B,MATCH(A36,SETORES!$A:$A,0)) -> Clientes | H36: Agosto/2026
A37: CAC | B37: Custo Fixo | C37: Material de uso coletivo (copa/limpeza) | F37: =IFERROR(D37*E37,0) -> 0 | G37: =INDEX(SETORES!$B:$B,MATCH(A37,SETORES!$A:$A,0)) -> Clientes | H37: Agosto/2026
A38: CAC | B38: Custo Variável | C38: Rescisões trabalhistas | F38: =IFERROR(D38*E38,0) -> 0 | G38: =INDEX(SETORES!$B:$B,MATCH(A38,SETORES!$A:$A,0)) -> Clientes | H38: Agosto/2026
A39: CAC | B39: Custo Fixo | C39: Stargrid | D39: 5 | E39: 1.87 | F39: =IFERROR(D39*E39,0) -> 9.35 | G39: =INDEX(SETORES!$B:$B,MATCH(A39,SETORES!$A:$A,0)) -> Clientes | H39: Agosto/2026
A40: CAC | B40: Custo Fixo | C40: Telefonia móvel corporativa | F40: =IFERROR(D40*E40,0) -> 0 | G40: =INDEX(SETORES!$B:$B,MATCH(A40,SETORES!$A:$A,0)) -> Clientes | H40: Agosto/2026
A41: Cobrança | B41: Custo Fixo | C41: Água e esgoto (rateio) | F41: =IFERROR(D41*E41,0) -> 0 | G41: =INDEX(SETORES!$B:$B,MATCH(A41,SETORES!$A:$A,0)) -> Clientes | H41: Agosto/2026
...

Sheet RESUMO REEMBOLSO
A1: RESUMO — REEMBOLSO POR EMPRESA
A3: Empresa | B3: Total de Custo Rateado (R$) | C3: Total de Royalty (R$) | D3: Custos Comerciais Diretos (R$) | E3: Total Geral a Cobrar (R$) | F3: % do Total Geral (custo) | G3: Mês
A4: Empresa Licenciada DX2 | B4: =SUMIFS(PARÂMETROS!$F:$F,PARÂMETROS!$C:$C,A4,PARÂMETROS!$J:$J,G4) -> 76157.1 | C4: =SUMIFS(PARÂMETROS!$H:$H,PARÂMETROS!$C:$C,A4,PARÂMETROS!$J:$J,G4) -> 0 | D4: =SUMIFS('COMERCIAL VAREJO'!$H:$H,'COMERCIAL VAREJO'!$B:$B,A4,'COMERCIAL VAREJO'!$A:$A,G4,'COMERCIAL VAREJO'!$C:$C,"<>") -> 0 | E4: =B4+C4+D4 -> 76157.1 | F4: =IFERROR(B4/B$12,0) -> 0.031841629 | G4: Junho/2026
A5: Empresa Licenciada H&A | B5: =SUMIFS(PARÂMETROS!$F:$F,PARÂMETROS!$C:$C,A5,PARÂMETROS!$J:$J,G5) -> 150715.63 | C5: =SUMIFS(PARÂMETROS!$H:$H,PARÂMETROS!$C:$C,A5,PARÂMETROS!$J:$J,G5) -> 0 | D5: =SUMIFS('COMERCIAL VAREJO'!$H:$H,'COMERCIAL VAREJO'!$B:$B,A5,'COMERCIAL VAREJO'!$A:$A,G5,'COMERCIAL VAREJO'!$C:$C,"<>") -> 0 | E5: =B5+C5+D5 -> 150715.63 | F5: =IFERROR(B5/B$12,0) -> 0.063014889 | G5: Junho/2026
A6: Empresa Licenciada SOLON ARAUJO | B6: =SUMIFS(PARÂMETROS!$F:$F,PARÂMETROS!$C:$C,A6,PARÂMETROS!$J:$J,G6) -> 171875.74 | C6: =SUMIFS(PARÂMETROS!$H:$H,PARÂMETROS!$C:$C,A6,PARÂMETROS!$J:$J,G6) -> 0 | D6: =SUMIFS('COMERCIAL VAREJO'!$H:$H,'COMERCIAL VAREJO'!$B:$B,A6,'COMERCIAL VAREJO'!$A:$A,G6,'COMERCIAL VAREJO'!$C:$C,"<>") -> 0 | E6: =B6+C6+D6 -> 171875.74 | F6: =IFERROR(B6/B$12,0) -> 0.071862029 | G6: Junho/2026
A7: Empresa Licenciada SOARES E LINS | B7: =SUMIFS(PARÂMETROS!$F:$F,PARÂMETROS!$C:$C,A7,PARÂMETROS!$J:$J,G7) -> 44130.681 | C7: =SUMIFS(PARÂMETROS!$H:$H,PARÂMETROS!$C:$C,A7,PARÂMETROS!$J:$J,G7) -> 0 | D7: =SUMIFS('COMERCIAL VAREJO'!$H:$H,'COMERCIAL VAREJO'!$B:$B,A7,'COMERCIAL VAREJO'!$A:$A,G7,'COMERCIAL VAREJO'!$C:$C,"<>") -> 0 | E7: =B7+C7+D7 -> 44130.681 | F7: =IFERROR(B7/B$12,0) -> 0.018451238 | G7: Junho/2026
A8: Empresa Licenciada SOARES E SILVA | B8: =SUMIFS(PARÂMETROS!$F:$F,PARÂMETROS!$C:$C,A8,PARÂMETROS!$J:$J,G8) -> 81282.875 | C8: =SUMIFS(PARÂMETROS!$H:$H,PARÂMETROS!$C:$C,A8,PARÂMETROS!$J:$J,G8) -> 0 | D8: =SUMIFS('COMERCIAL VAREJO'!$H:$H,'COMERCIAL VAREJO'!$B:$B,A8,'COMERCIAL VAREJO'!$A:$A,G8,'COMERCIAL VAREJO'!$C:$C,"<>") -> 0 | E8: =B8+C8+D8 -> 81282.875 | F8: =IFERROR(B8/B$12,0) -> 0.033984739 | G8: Junho/2026
A9: Empresa Licenciada SOUZA E SILVA | B9: =SUMIFS(PARÂMETROS!$F:$F,PARÂMETROS!$C:$C,A9,PARÂMETROS!$J:$J,G9) -> 54691.145 | C9: =SUMIFS(PARÂMETROS!$H:$H,PARÂMETROS!$C:$C,A9,PARÂMETROS!$J:$J,G9) -> 0 | D9: =SUMIFS('COMERCIAL VAREJO'!$H:$H,'COMERCIAL VAREJO'!$B:$B,A9,'COMERCIAL VAREJO'!$A:$A,G9,'COMERCIAL VAREJO'!$C:$C,"<>") -> 0 | E9: =B9+C9+D9 -> 54691.145 | F9: =IFERROR(B9/B$12,0) -> 0.022866616 | G9: Junho/2026
A10: Empresa Licenciada VOICENET | B10: =SUMIFS(PARÂMETROS!$F:$F,PARÂMETROS!$C:$C,A10,PARÂMETROS!$J:$J,G10) -> 57686.948 | C10: =SUMIFS(PARÂMETROS!$H:$H,PARÂMETROS!$C:$C,A10,PARÂMETROS!$J:$J,G10) -> 0 | D10: =SUMIFS('COMERCIAL VAREJO'!$H:$H,'COMERCIAL VAREJO'!$B:$B,A10,'COMERCIAL VAREJO'!$A:$A,G10,'COMERCIAL VAREJO'!$C:$C,"<>") -> 0 | E10: =B10+C10+D10 -> 57686.948 | F10: =IFERROR(B10/B$12,0) -> 0.024119175 | G10: Junho/2026
A11: DTEL (uso próprio) | B11: =SUMIFS(PARÂMETROS!$F:$F,PARÂMETROS!$C:$C,A11,PARÂMETROS!$J:$J,G11) -> 1755206.2 | C11: =SUMIFS(PARÂMETROS!$H:$H,PARÂMETROS!$C:$C,A11,PARÂMETROS!$J:$J,G11) -> 0 | D11: =SUMIFS('COMERCIAL VAREJO'!$H:$H,'COMERCIAL VAREJO'!$B:$B,A11,'COMERCIAL VAREJO'!$A:$A,G11,'COMERCIAL VAREJO'!$C:$C,"<>") -> 0 | E11: =B11+C11+D11 -> 1755206.2 | F11: =IFERROR(B11/B$12,0) -> 0.73385968 | G11: Junho/2026
A12: TOTAL GERAL — Junho/2026 | B12: =SUM(B4:B11) -> 2391746.3 | C12: =SUM(C4:C11) -> 0 | D12: =SUM(D4:D11) -> 0 | E12: =SUM(E4:E11) -> 2391746.3
A14: Empresa Licenciada DX2 | B14: =SUMIFS(PARÂMETROS!$F:$F,PARÂMETROS!$C:$C,A14,PARÂMETROS!$J:$J,G14) -> 65465.085 | C14: =SUMIFS(PARÂMETROS!$H:$H,PARÂMETROS!$C:$C,A14,PARÂMETROS!$J:$J,G14) -> 0 | D14: =SUMIFS('COMERCIAL VAREJO'!$H:$H,'COMERCIAL VAREJO'!$B:$B,A14,'COMERCIAL VAREJO'!$A:$A,G14,'COMERCIAL VAREJO'!$C:$C,"<>") -> 0 | E14: =B14+C14+D14 -> 65465.085 | F14: =IFERROR(B14/B$22,0) -> 0.031665912 | G14: Maio/2026
A15: Empresa Licenciada H&A | B15: =SUMIFS(PARÂMETROS!$F:$F,PARÂMETROS!$C:$C,A15,PARÂMETROS!$J:$J,G15) -> 132760.39 | C15: =SUMIFS(PARÂMETROS!$H:$H,PARÂMETROS!$C:$C,A15,PARÂMETROS!$J:$J,G15) -> 0 | D15: =SUMIFS('COMERCIAL VAREJO'!$H:$H,'COMERCIAL VAREJO'!$B:$B,A15,'COMERCIAL VAREJO'!$A:$A,G15,'COMERCIAL VAREJO'!$C:$C,"<>") -> 0 | E15: =B15+C15+D15 -> 132760.39 | F15: =IFERROR(B15/B$22,0) -> 0.064217114 | G15: Maio/2026
A16: Empresa Licenciada SOLON ARAUJO | B16: =SUMIFS(PARÂMETROS!$F:$F,PARÂMETROS!$C:$C,A16,PARÂMETROS!$J:$J,G16) -> 150306.29 | C16: =SUMIFS(PARÂMETROS!$H:$H,PARÂMETROS!$C:$C,A16,PARÂMETROS!$J:$J,G16) -> 0 | D16: =SUMIFS('COMERCIAL VAREJO'!$H:$H,'COMERCIAL VAREJO'!$B:$B,A16,'COMERCIAL VAREJO'!$A:$A,G16,'COMERCIAL VAREJO'!$C:$C,"<>") -> 0 | E16: =B16+C16+D16 -> 150306.29 | F16: =IFERROR(B16/B$22,0) -> 0.072704185 | G16: Maio/2026
A17: Empresa Licenciada SOARES E LINS | B17: =SUMIFS(PARÂMETROS!$F:$F,PARÂMETROS!$C:$C,A17,PARÂMETROS!$J:$J,G17) -> 38334.918 | C17: =SUMIFS(PARÂMETROS!$H:$H,PARÂMETROS!$C:$C,A17,PARÂMETROS!$J:$J,G17) -> 0 | D17: =SUMIFS('COMERCIAL VAREJO'!$H:$H,'COMERCIAL VAREJO'!$B:$B,A17,'COMERCIAL VAREJO'!$A:$A,G17,'COMERCIAL VAREJO'!$C:$C,"<>") -> 0 | E17: =B17+C17+D17 -> 38334.918 | F17: =IFERROR(B17/B$22,0) -> 0.018542864 | G17: Maio/2026
A18: Empresa Licenciada SOARES E SILVA | B18: =SUMIFS(PARÂMETROS!$F:$F,PARÂMETROS!$C:$C,A18,PARÂMETROS!$J:$J,G18) -> 71152.656 | C18: =SUMIFS(PARÂMETROS!$H:$H,PARÂMETROS!$C:$C,A18,PARÂMETROS!$J:$J,G18) -> 0 | D18: =SUMIFS('COMERCIAL VAREJO'!$H:$H,'COMERCIAL VAREJO'!$B:$B,A18,'COMERCIAL VAREJO'!$A:$A,G18,'COMERCIAL VAREJO'!$C:$C,"<>") -> 0 | E18: =B18+C18+D18 -> 71152.656 | F18: =IFERROR(B18/B$22,0) -> 0.03441703 | G18: Maio/2026
A19: Empresa Licenciada SOUZA E SILVA | B19: =SUMIFS(PARÂMETROS!$F:$F,PARÂMETROS!$C:$C,A19,PARÂMETROS!$J:$J,G19) -> 47843.858 | C19: =SUMIFS(PARÂMETROS!$H:$H,PARÂMETROS!$C:$C,A19,PARÂMETROS!$J:$J,G19) -> 0 | D19: =SUMIFS('COMERCIAL VAREJO'!$H:$H,'COMERCIAL VAREJO'!$B:$B,A19,'COMERCIAL VAREJO'!$A:$A,G19,'COMERCIAL VAREJO'!$C:$C,"<>") -> 0 | E19: =B19+C19+D19 -> 47843.858 | F19: =IFERROR(B19/B$22,0) -> 0.023142403 | G19: Maio/2026
A20: Empresa Licenciada VOICENET | B20: =SUMIFS(PARÂMETROS!$F:$F,PARÂMETROS!$C:$C,A20,PARÂMETROS!$J:$J,G20) -> 51202.106 | C20: =SUMIFS(PARÂMETROS!$H:$H,PARÂMETROS!$C:$C,A20,PARÂMETROS!$J:$J,G20) -> 0 | D20: =SUMIFS('COMERCIAL VAREJO'!$H:$H,'COMERCIAL VAREJO'!$B:$B,A20,'COMERCIAL VAREJO'!$A:$A,G20,'COMERCIAL VAREJO'!$C:$C,"<>") -> 0 | E20: =B20+C20+D20 -> 51202.106 | F20: =IFERROR(B20/B$22,0) -> 0.024766811 | G20: Maio/2026
A21: DTEL (uso próprio) | B21: =SUMIFS(PARÂMETROS!$F:$F,PARÂMETROS!$C:$C,A21,PARÂMETROS!$J:$J,G21) -> 1510302.4 | C21: =SUMIFS(PARÂMETROS!$H:$H,PARÂMETROS!$C:$C,A21,PARÂMETROS!$J:$J,G21) -> 0 | D21: =SUMIFS('COMERCIAL VAREJO'!$H:$H,'COMERCIAL VAREJO'!$B:$B,A21,'COMERCIAL VAREJO'!$A:$A,G21,'COMERCIAL VAREJO'!$C:$C,"<>") -> 0 | E21: =B21+C21+D21 -> 1510302.4 | F21: =IFERROR(B21/B$22,0) -> 0.73054368 | G21: Maio/2026
A22: TOTAL GERAL — Maio/2026 | B22: =SUM(B14:B21) -> 2067367.7 | C22: =SUM(C14:C21) -> 0 | D22: =SUM(D14:D21) -> 0 | E22: =SUM(E14:E21) -> 2067367.7
A24: Empresa Licenciada DX2 | B24: =SUMIFS(PARÂMETROS!$F:$F,PARÂMETROS!$C:$C,A24,PARÂMETROS!$J:$J,G24) -> 81468.123 | C24: =SUMIFS(PARÂMETROS!$H:$H,PARÂMETROS!$C:$C,A24,PARÂMETROS!$J:$J,G24) -> 0 | D24: =SUMIFS('COMERCIAL VAREJO'!$H:$H,'COMERCIAL VAREJO'!$B:$B,A24,'COMERCIAL VAREJO'!$A:$A,G24,'COMERCIAL VAREJO'!$C:$C,"<>") -> 0 | E24: =B24+C24+D24 -> 81468.123 | F24: =IFERROR(B24/B$32,0) -> 0.031662514 | G24: Julho/2026
A25: Empresa Licenciada H&A | B25: =SUMIFS(PARÂMETROS!$F:$F,PARÂMETROS!$C:$C,A25,PARÂMETROS!$J:$J,G25) -> 147726.92 | C25: =SUMIFS(PARÂMETROS!$H:$H,PARÂMETROS!$C:$C,A25,PARÂMETROS!$J:$J,G25) -> 0 | D25: =SUMIFS('COMERCIAL VAREJO'!$H:$H,'COMERCIAL VAREJO'!$B:$B,A25,'COMERCIAL VAREJO'!$A:$A,G25,'COMERCIAL VAREJO'!$C:$C,"<>") -> 0 | E25: =B25+C25+D25 -> 147726.92 | F25: =IFERROR(B25/B$32,0) -> 0.057413936 | G25: Julho/2026
A26: Empresa Licenciada SOLON ARAUJO | B26: =SUMIFS(PARÂMETROS!$F:$F,PARÂMETROS!$C:$C,A26,PARÂMETROS!$J:$J,G26) -> 179881.52 | C26: =SUMIFS(PARÂMETROS!$H:$H,PARÂMETROS!$C:$C,A26,PARÂMETROS!$J:$J,G26) -> 0 | D26: =SUMIFS('COMERCIAL VAREJO'!$H:$H,'COMERCIAL VAREJO'!$B:$B,A26,'COMERCIAL VAREJO'!$A:$A,G26,'COMERCIAL VAREJO'!$C:$C,"<>") -> 0 | E26: =B26+C26+D26 -> 179881.52 | F26: =IFERROR(B26/B$32,0) -> 0.069910793 | G26: Julho/2026
A27: Empresa Licenciada SOARES E LINS | B27: =SUMIFS(PARÂMETROS!$F:$F,PARÂMETROS!$C:$C,A27,PARÂMETROS!$J:$J,G27) -> 45812.57 | C27: =SUMIFS(PARÂMETROS!$H:$H,PARÂMETROS!$C:$C,A27,PARÂMETROS!$J:$J,G27) -> 0 | D27: =SUMIFS('COMERCIAL VAREJO'!$H:$H,'COMERCIAL VAREJO'!$B:$B,A27,'COMERCIAL VAREJO'!$A:$A,G27,'COMERCIAL VAREJO'!$C:$C,"<>") -> 0 | E27: =B27+C27+D27 -> 45812.57 | F27: =IFERROR(B27/B$32,0) -> 0.017805015 | G27: Julho/2026
A28: Empresa Licenciada SOARES E SILVA | B28: =SUMIFS(PARÂMETROS!$F:$F,PARÂMETROS!$C:$C,A28,PARÂMETROS!$J:$J,G28) -> 85737.863 | C28: =SUMIFS(PARÂMETROS!$H:$H,PARÂMETROS!$C:$C,A28,PARÂMETROS!$J:$J,G28) -> 0 | D28: =SUMIFS('COMERCIAL VAREJO'!$H:$H,'COMERCIAL VAREJO'!$B:$B,A28,'COMERCIAL VAREJO'!$A:$A,G28,'COMERCIAL VAREJO'!$C:$C,"<>") -> 0 | E28: =B28+C28+D28 -> 85737.863 | F28: =IFERROR(B28/B$32,0) -> 0.033321944 | G28: Julho/2026
A29: Empresa Licenciada SOUZA E SILVA | B29: =SUMIFS(PARÂMETROS!$F:$F,PARÂMETROS!$C:$C,A29,PARÂMETROS!$J:$J,G29) -> 57512.379 | C29: =SUMIFS(PARÂMETROS!$H:$H,PARÂMETROS!$C:$C,A29,PARÂMETROS!$J:$J,G29) -> 0 | D29: =SUMIFS('COMERCIAL VAREJO'!$H:$H,'COMERCIAL VAREJO'!$B:$B,A29,'COMERCIAL VAREJO'!$A:$A,G29,'COMERCIAL VAREJO'!$C:$C,"<>") -> 0 | E29: =B29+C29+D29 -> 57512.379 | F29: =IFERROR(B29/B$32,0) -> 0.022352135 | G29: Julho/2026
A30: Empresa Licenciada VOICENET | B30: =SUMIFS(PARÂMETROS!$F:$F,PARÂMETROS!$C:$C,A30,PARÂMETROS!$J:$J,G30) -> 61272.918 | C30: =SUMIFS(PARÂMETROS!$H:$H,PARÂMETROS!$C:$C,A30,PARÂMETROS!$J:$J,G30) -> 0 | D30: =SUMIFS('COMERCIAL VAREJO'!$H:$H,'COMERCIAL VAREJO'!$B:$B,A30,'COMERCIAL VAREJO'!$A:$A,G30,'COMERCIAL VAREJO'!$C:$C,"<>") -> 0 | E30: =B30+C30+D30 -> 61272.918 | F30: =IFERROR(B30/B$32,0) -> 0.023813665 | G30: Julho/2026
A31: DTEL (uso próprio) | B31: =SUMIFS(PARÂMETROS!$F:$F,PARÂMETROS!$C:$C,A31,PARÂMETROS!$J:$J,G31) -> 1913602.7 | C31: =SUMIFS(PARÂMETROS!$H:$H,PARÂMETROS!$C:$C,A31,PARÂMETROS!$J:$J,G31) -> 0 | D31: =SUMIFS('COMERCIAL VAREJO'!$H:$H,'COMERCIAL VAREJO'!$B:$B,A31,'COMERCIAL VAREJO'!$A:$A,G31,'COMERCIAL VAREJO'!$C:$C,"<>") -> 0 | E31: =B31+C31+D31 -> 1913602.7 | F31: =IFERROR(B31/B$32,0) -> 0.74372 | G31: Julho/2026
A32: TOTAL GERAL — Julho/2026 | B32: =SUM(B24:B31) -> 2573015 | C32: =SUM(C24:C31) -> 0 | D32: =SUM(D24:D31) -> 0 | E32: =SUM(E24:E31) -> 2573015
A33: Empresa Licenciada DX2 | B33: =SUMIFS(PARÂMETROS!$F:$F,PARÂMETROS!$C:$C,A33,PARÂMETROS!$J:$J,G33) -> 80480.054 | C33: =SUMIFS(PARÂMETROS!$H:$H,PARÂMETROS!$C:$C,A33,PARÂMETROS!$J:$J,G33) -> 0 | D33: =SUMIFS('COMERCIAL VAREJO'!$H:$H,'COMERCIAL VAREJO'!$B:$B,A33,'COMERCIAL VAREJO'!$A:$A,G33,'COMERCIAL VAREJO'!$C:$C,"<>") -> 0 | E33: =B33+C33+D33 -> 80480.054 | F33: =IFERROR(B33/B$32,0) -> 0.031278502 | G33: Agosto/2026
A34: Empresa Licenciada H&A | G34: Agosto/2026
A35: Empresa Licenciada SOLON ARAUJO | B35: =SUMIFS(PARÂMETROS!$F:$F,PARÂMETROS!$C:$C,A35,PARÂMETROS!$J:$J,G35) -> 180230.56 | C35: =SUMIFS(PARÂMETROS!$H:$H,PARÂMETROS!$C:$C,A35,PARÂMETROS!$J:$J,G35) -> 0 | D35: =SUMIFS('COMERCIAL VAREJO'!$H:$H,'COMERCIAL VAREJO'!$B:$B,A35,'COMERCIAL VAREJO'!$A:$A,G35,'COMERCIAL VAREJO'!$C:$C,"<>") -> 0 | E35: =B35+C35+D35 -> 180230.56 | F35: =IFERROR(B35/B$32,0) -> 0.070046447 | G35: Agosto/2026
A36: Empresa Licenciada SOARES E LINS | B36: =SUMIFS(PARÂMETROS!$F:$F,PARÂMETROS!$C:$C,A36,PARÂMETROS!$J:$J,G36) -> 45544.912 | C36: =SUMIFS(PARÂMETROS!$H:$H,PARÂMETROS!$C:$C,A36,PARÂMETROS!$J:$J,G36) -> 0 | D36: =SUMIFS('COMERCIAL VAREJO'!$H:$H,'COMERCIAL VAREJO'!$B:$B,A36,'COMERCIAL VAREJO'!$A:$A,G36,'COMERCIAL VAREJO'!$C:$C,"<>") -> 0 | E36: =B36+C36+D36 -> 45544.912 | F36: =IFERROR(B36/B$32,0) -> 0.01770099 | G36: Agosto/2026
A37: Empresa Licenciada SOARES E SILVA | B37: =SUMIFS(PARÂMETROS!$F:$F,PARÂMETROS!$C:$C,A37,PARÂMETROS!$J:$J,G37) -> 82987.231 | C37: =SUMIFS(PARÂMETROS!$H:$H,PARÂMETROS!$C:$C,A37,PARÂMETROS!$J:$J,G37) -> 0 | D37: =SUMIFS('COMERCIAL VAREJO'!$H:$H,'COMERCIAL VAREJO'!$B:$B,A37,'COMERCIAL VAREJO'!$A:$A,G37,'COMERCIAL VAREJO'!$C:$C,"<>") -> 0 | E37: =B37+C37+D37 -> 82987.231 | F37: =IFERROR(B37/B$32,0) -> 0.032252914 | G37: Agosto/2026
A38: Empresa Licenciada SOUZA E SILVA | B38: =SUMIFS(PARÂMETROS!$F:$F,PARÂMETROS!$C:$C,A38,PARÂMETROS!$J:$J,G38) -> 57111.55 | C38: =SUMIFS(PARÂMETROS!$H:$H,PARÂMETROS!$C:$C,A38,PARÂMETROS!$J:$J,G38) -> 0 | D38: =SUMIFS('COMERCIAL VAREJO'!$H:$H,'COMERCIAL VAREJO'!$B:$B,A38,'COMERCIAL VAREJO'!$A:$A,G38,'COMERCIAL VAREJO'!$C:$C,"<>") -> 0 | E38: =B38+C38+D38 -> 57111.55 | F38: =IFERROR(B38/B$32,0) -> 0.022196353 | G38: Agosto/2026
A39: Empresa Licenciada VOICENET | B39: =SUMIFS(PARÂMETROS!$F:$F,PARÂMETROS!$C:$C,A39,PARÂMETROS!$J:$J,G39) -> 60391.242 | C39: =SUMIFS(PARÂMETROS!$H:$H,PARÂMETROS!$C:$C,A39,PARÂMETROS!$J:$J,G39) -> 0 | D39: =SUMIFS('COMERCIAL VAREJO'!$H:$H,'COMERCIAL VAREJO'!$B:$B,A39,'COMERCIAL VAREJO'!$A:$A,G39,'COMERCIAL VAREJO'!$C:$C,"<>") -> 0 | E39: =B39+C39+D39 -> 60391.242 | F39: =IFERROR(B39/B$32,0) -> 0.023471002 | G39: Agosto/2026
A40: DTEL (uso próprio) | B40: =SUMIFS(PARÂMETROS!$F:$F,PARÂMETROS!$C:$C,A40,PARÂMETROS!$J:$J,G40) -> 1822826.8 | C40: =SUMIFS(PARÂMETROS!$H:$H,PARÂMETROS!$C:$C,A40,PARÂMETROS!$J:$J,G40) -> 0 | D40: =SUMIFS('COMERCIAL VAREJO'!$H:$H,'COMERCIAL VAREJO'!$B:$B,A40,'COMERCIAL VAREJO'!$A:$A,G40,'COMERCIAL VAREJO'!$C:$C,"<>") -> 0 | E40: =B40+C40+D40 -> 1822826.8 | F40: =IFERROR(B40/B$32,0) -> 0.70844001 | G40: Agosto/2026
A41: TOTAL GERAL — Agosto/2026 | B41: =SUM(B33:B40) -> 2329572.3 | C41: =SUM(C33:C40) -> 0 | D41: =SUM(D33:D40) -> 0 | E41: =SUM(E33:E40) -> 2329572.3
A44: Nota: o Total de Custo Rateado deve ser igual ao TOTAL GERAL da aba SETORES. Custos Comerciais Diretos vêm da aba COMERCIAL (custos já atribuídos diretamente a cada empresa, sem % de rateio). O Total de Royalty só existe se algum % Royalty foi definido em PARÂMETROS (padrão é 0%, sem royalty).

Sheet COMERCIAL VAREJO
A1: COMERCIAL VAREJO — CUSTOS DIRETOS POR COORDENADOR/EQUIPE (equipe de vendas externas)
A2: Cada equipe é o COORDENADOR/GERENTE da planilha de vendas PAP. Folha Trabalhista e Combustível são valores REAIS, cruzados pelo nome do colaborador (folha: 99 de 120 ativos encontrados; combustível: conforme arquivo de combustível). Vale Transporte, RH, DP, SST, Gympass, Stargrid, Fardamento e Linhas móveis não têm nome de colaborador na fonte — o valor total de cada empresa é RATEADO entre as equipes que têm gente daquela empresa, proporcional ao nº de colaboradores (E-mail do departamento é rateado só entre executivo/supervisor/coordenador/líder, que são quem usa). Rescisões foram excluídas da cobrança (sem fonte confirmada de nome/empresa/mês). Estes valores somados alimentam a coluna 'Custos Comerciais Diretos' do RESUMO REEMBOLSO.
A4: COMPOSIÇÃO DAS EQUIPES
A5: Coordenador/Equipe | B5: Empresa | C5: Total Ativos | D5: Vendedores Fixos (PAP) | E5: Executivos | F5: Outros cargos
A6: ELTHON MENEZES | B6: DTEL | C6: 39 | D6: 33 | E6: 2 | F6: MOTORISTA: 2, SUPERVISOR: 2
A7: GABRIEL LIMA | B7: DTEL | C7: 9 | D7: 9 | E7: 0 | F7: —
A8: LUCAS BONIFÁCIO | B8: DTEL | C8: 7 | D8: 6 | E8: 1 | F8: —
A9: MICHELANGELO | B9: DTEL | C9: 11 | D9: 8 | E9: 1 | F9: MOTORISTA: 1, SUPERVISOR: 1
A10: MICHELANGELO | B10: Voicenet | C10: 2 | D10: 1 | E10: 1 | F10: —
A11: TARCIZIO MEIRELES | B11: DTEL | C11: 18 | D11: 14 | E11: 2 | F11: MOTORISTA: 1, SUPERVISOR: 1
A12: TARCIZIO MEIRELES | B12: Solon Araújo | C12: 2 | D12: 1 | E12: 1 | F12: —
A13: TARCIZIO MEIRELES | B13: Souza e Silva | C13: 5 | D13: 5 | E13: 0 | F13: —
A14: TIAGO | B14: DX2 | C14: 8 | D14: 7 | E14: 0 | F14: LÍDER: 1
A15: TIAGO | B15: H&A | C15: 2 | D15: 1 | E15: 0 | F15: LÍDER: 1
A16: TIAGO | B16: Soares e Silva | C16: 11 | D16: 9 | E16: 1 | F16: SUPERVISOR: 1
A17: VITOR LINS | B17: Soares e Lins | C17: 1 | D17: 0 | E17: 0 | F17: LÍDER: 1
A19: CUSTOS DIRETOS — RATEADOS/REAIS POR COORDENADOR/EQUIPE
A20: Mês | B20: Empresa | C20: Categoria | D20: Despesa | E20: Coordenador/Equipe | F20: Quantidade | G20: Valor Unitário (R$) | H20: Valor (R$) | I20: Origem
A21: Junho/2026 | B21: DTEL | C21: Pessoal | D21: Folha Trabalhista com impostos do mês | E21: ELTHON MENEZES | F21: 1 | G21: 59982.059 | H21: 59982.059 | I21: Real (cruzado por nome, 38/42 encontrados) | Ajustado 24/08/2026: subtraído o custo de folha de Pedro Moreira do Amaral (R$ 4741.11), que passou a ter linha própria de van/kombi, para não contar 2x. | Ajustado 24/08/2026: subtraído o custo de folha de Felipe Lopes de Souza (R$ 5374.25), que passou a ter linha própria de van/kombi, para não contar 2x. | Ajustado 24/08/2026: subtraído o custo de folha de Alvaro Henrique de Sousa (R$ 4859.05), que passou a ter linha própria de van/kombi, para não contar 2x.
A22: Junho/2026 | B22: DTEL | C22: Pessoal | D22: Vale Transporte | E22: ELTHON MENEZES | F22: 1 | G22: 1236.86 | H22: 1236.86 | I22: Estimado (fatia proporcional ao nº de colaboradores da equipe, sem taxa fixa por pessoa), fatia de 39 colaboradores da equipe
A23: Junho/2026 | B23: DTEL | C23: Pessoal | D23: Despesas com RH | E23: ELTHON MENEZES | F23: 39 | G23: 28.31 | H23: 1104.09 | I23: Real (taxa fixa por colaborador, confirmada em todas as empresas)
A24: Junho/2026 | B24: DTEL | C24: Pessoal | D24: Despesas com DP | E24: ELTHON MENEZES | F24: 39 | G24: 47.79 | H24: 1863.81 | I24: Real (taxa fixa por colaborador, confirmada em todas as empresas)
A25: Junho/2026 | B25: DTEL | C25: Segurança do Trabalho | D25: Despesas com SST | E25: ELTHON MENEZES | F25: 39 | G25: 64.54 | H25: 2517.06 | I25: Real (taxa fixa por colaborador, confirmada em todas as empresas)
A26: Junho/2026 | B26: DTEL | C26: Segurança do Trabalho | D26: Despesas SST exames | E26: ELTHON MENEZES | F26: 1 | G26: 142.07 | H26: 142.07 | I26: Estimado (fatia proporcional ao nº de colaboradores da equipe, sem taxa fixa por pessoa), fatia de 39 colaboradores da equipe
A27: Junho/2026 | B27: DTEL | C27: Benefícios | D27: Gympass | E27: ELTHON MENEZES | F27: 39 | G27: 10.05 | H27: 391.95 | I27: Real (taxa fixa por colaborador, confirmada em todas as empresas)
A28: Junho/2026 | B28: DTEL | C28: Benefícios | D28: Stargrid | E28: ELTHON MENEZES | F28: 39 | G28: 2.07 | H28: 80.73 | I28: Real (taxa fixa por colaborador, confirmada em todas as empresas)
A29: Junho/2026 | B29: DTEL | C29: Fardamento | D29: Novo Fardamento | E29: ELTHON MENEZES | F29: 1 | G29: 764.48 | H29: 764.48 | I29: Estimado (fatia proporcional ao nº de colaboradores da equipe, sem taxa fixa por pessoa), fatia de 39 colaboradores da equipe
A30: Junho/2026 | B30: DTEL | C30: Fardamento | D30: Substituição extra de Fardamento | E30: ELTHON MENEZES | F30: 1 | G30: 1150.7 | H30: 1150.7 | I30: Estimado (fatia proporcional ao nº de colaboradores da equipe, sem taxa fixa por pessoa), fatia de 39 colaboradores da equipe
A31: Junho/2026 | B31: DTEL | C31: Estrutura/Infra | D31: Linhas moveis (FIQUE MÓVEL) | E31: ELTHON MENEZES | F31: 42 | G31: 30 | H31: =F31*G31 -> 1260 | I31: Real (taxa fixa por colaborador, confirmada em todas as empresas)
A32: Junho/2026 | B32: DTEL | C32: Frota/Combustível | D32: Consumo de combustível | E32: ELTHON MENEZES | F32: 1 | G32: 370.8 | H32: =F32*G32 -> 370.8 | I32: Real (cruzado por nome, planilha de combustível) | Ajustado 24/08/2026: subtraído o combustível de Pedro Moreira do Amaral (R$ 1887.24), que passou a ter linha própria de van/kombi, para não contar 2x. | Ajustado 24/08/2026: subtraído o combustível de Felipe Lopes de Souza (R$ 3112.86), que passou a ter linha própria de van/kombi, para não contar 2x.
A33: Junho/2026 | B33: DTEL | C33: Pessoal | D33: Folha Trabalhista com impostos do mês | E33: GABRIEL LIMA | F33: 1 | G33: 7035.95 | H33: =F33*G33 -> 7035.95 | I33: Real (cruzado por nome, 3/9 encontrados)
A34: Junho/2026 | B34: DTEL | C34: Pessoal | D34: Vale Transporte | E34: GABRIEL LIMA | F34: 1 | G34: 285.43 | H34: 285.43 | I34: Estimado (fatia proporcional ao nº de colaboradores da equipe, sem taxa fixa por pessoa), fatia de 9 colaboradores da equipe
A35: Junho/2026 | B35: DTEL | C35: Pessoal | D35: Despesas com RH | E35: GABRIEL LIMA | F35: 9 | G35: 28.31 | H35: =F35*G35 -> 254.79 | I35: Real (taxa fixa por colaborador, confirmada em todas as empresas)
A36: Junho/2026 | B36: DTEL | C36: Pessoal | D36: Despesas com DP | E36: GABRIEL LIMA | F36: 9 | G36: 47.79 | H36: =F36*G36 -> 430.11 | I36: Real (taxa fixa por colaborador, confirmada em todas as empresas)
A37: Junho/2026 | B37: DTEL | C37: Segurança do Trabalho | D37: Despesas com SST | E37: GABRIEL LIMA | F37: 9 | G37: 64.54 | H37: =F37*G37 -> 580.86 | I37: Real (taxa fixa por colaborador, confirmada em todas as empresas)
A38: Junho/2026 | B38: DTEL | C38: Segurança do Trabalho | D38: Despesas SST exames | E38: GABRIEL LIMA | F38: 1 | G38: 32.79 | H38: 32.79 | I38: Estimado (fatia proporcional ao nº de colaboradores da equipe, sem taxa fixa por pessoa), fatia de 9 colaboradores da equipe
A39: Junho/2026 | B39: DTEL | C39: Benefícios | D39: Gympass | E39: GABRIEL LIMA | F39: 9 | G39: 10.05 | H39: =F39*G39 -> 90.45 | I39: Real (taxa fixa por colaborador, confirmada em todas as empresas)
